Workbook

Sheet PORTS SUMMARY
A1: POD | B1: (All)
A2: MODEL | B2: (All)
A4: Count of Admin State | B4: Column Labels
B5: down | D5: up | G5: Grand Total
B6: Breake-Out port | C6: down | D6: Breake-Out port | E6: down | F6: up
A7: Row Labels | B7: #N/A | D7: #N/A | F7: none
A8: 9LF_IXT1_10112_01 | C8: 3 | E8: 10 | F8: 41 | G8: 54
A9: 9LF_IXT1_10218_01 | C9: 13 | E9: 74 | F9: 9 | G9: 96
A10: 9LF_IXT1_10218_02 | C10: 3 | E10: 83 | F10: 10 | G10: 96
A11: 9LF_IXT1_10218_03 | C11: 13 | E11: 71 | F11: 12 | G11: 96
A12: 9LF_IXT1_10218_04 | C12: 3 | E12: 78 | F12: 15 | G12: 96
A13: 9LF_IXT1_10318_01 | C13: 1 | E13: 47 | F13: 48 | G13: 96
A14: 9LF_IXT1_10418_01 | C14: 16 | E14: 36 | F14: 44 | G14: 96
A15: 9LF_IXT1_10518_01 | C15: 13 | E15: 44 | F15: 39 | G15: 96
A16: 9LF_IXT1_10618_01 | C16: 12 | E16: 43 | F16: 41 | G16: 96
A17: 9LF_IXT1_10718_01 | C17: 3 | E17: 45 | F17: 48 | G17: 96
A18: 9LF_IXT1_10718_02 | C18: 22 | E18: 1 | F18: 31 | G18: 54
A19: 9LF_IXT1_10718_03 | C19: 22 | F19: 32 | G19: 54
A20: 9LF_IXT1_10818_01 | C20: 4 | E20: 59 | F20: 33 | G20: 96
A21: 9LF_IXT1_10918_01 | C21: 13 | E21: 50 | F21: 33 | G21: 96
A22: 9LF_IXT1_10918_02 | E22: 72 | F22: 24 | G22: 96
A23: 9LF_IXT1_10918_03 | C23: 46 | F23: 8 | G23: 54
A24: 9LF_IXT1_10918_04 | C24: 46 | F24: 8 | G24: 54
A25: 9LF_IXT1_11018_01 | C25: 13 | E25: 52 | F25: 31 | G25: 96
A26: 9LF_IXT1_11018_02 | E26: 77 | F26: 19 | G26: 96
A27: 9LF_IXT1_11118_01 | C27: 18 | E27: 37 | F27: 41 | G27: 96
A28: 9LF_IXT1_11118_02 | E28: 94 | F28: 2 | G28: 96
A29: 9LF_IXT1_11218_01 | C29: 13 | E29: 38 | F29: 45 | G29: 96
A30: 9LF_IXT1_11218_02 | C30: 9 | E30: 85 | F30: 2 | G30: 96
A31: 9LF_IXT1_11318_01 | C31: 22 | E31: 5 | F31: 69 | G31: 96
A32: 9LF_IXT1_11318_02 | C32: 1 | E32: 46 | F32: 7 | G32: 54
A33: 9LF_IXT1_11418_01 | C33: 22 | E33: 10 | F33: 64 | G33: 96
A34: 9LF_IXT1_11418_02 | C34: 1 | E34: 40 | F34: 13 | G34: 54
A35: 9LF_IXT1_11518_01 | C35: 10 | E35: 51 | F35: 35 | G35: 96
A36: 9LF_IXT1_11618_01 | C36: 11 | E36: 52 | F36: 33 | G36: 96
A37: 9LF_IXT1_11718_01 | C37: 1 | E37: 69 | F37: 26 | G37: 96
A38: 9LF_IXT1_20114_01 | C38: 2 | E38: 9 | F38: 43 | G38: 54
A39: 9LF_IXT1_20219_01 | C39: 2 | E39: 68 | F39: 26 | G39: 96
A40: 9LF_IXT1_20219_02 | C40: 1 | E40: 34 | F40: 19 | G40: 54
... A66: 9LF_IXT2_10818_04 | C66: 68 | E66: 1 | F66: 27 | G66: 96
...

Sheet POD 2 SUMMARY
A1: pod | B1: (All)
A2: MODEL | B2: (All)
A4: Count of oper state | B4: Column Labels
A5: Row Labels | B5: down | C5: up | D5: Grand Total
A6: 100G | B6: 990 | C6: 12 | D6: 1002
A7: 100M | B7: 141 | C7: 739 | D7: 880
A8: 10G | B8: 3716 | C8: 5203 | D8: 8919
A9: 1G | B9: 763 | C9: 2525 | D9: 3288
A10: 25G | B10: 2980 | C10: 8 | D10: 2988
A11: 40G | B11: 268 | C11: 1160 | D11: 1428
A12: auto | B12: 17 | D12: 17
A13: Grand Total | B13: 8875 | C13: 9647 | D13: 18522

Sheet CONCENTRATED
A1: NODE | B1: POD | C1: HOSTNAME | D1: PORT | E1: Admin State | F1: Operational State | G1: Reason | H1: Description | I1: MODEL | J1: VPC | K1: VPC2 | L1: ID | M1: PG | N1: ISEL | O1: STATIC PORT | P1: L3OUT | Q1: STATIC PORT P/LEAF | R1: PORTS P/LEAF
A2: 101 | B2: 1 | C2: =VLOOKUP(VALUE(Table5[[#This Row],[NODE]]),LEAF_INFO!B:H,6,0) | D2: eth1/33 | E2: down | F2: down | G2: =VLOOKUP(_xlfn.CONCAT(Table5[[#This Row],[NODE]],Table5[[#This Row],[PORT]]),PORTS_!A:G,7,0) | I2: =VLOOKUP(VALUE(Table5[[#This Row],[NODE]]),LEAF_INFO!B:H,7,0) | J2: =ISNUMBER(SEARCH("vpc-leaf", SUBSTITUTE(LOWER(K2), "_", "-"))) | K2: =_xlfn.IFNA(VLOOKUP(VALUE(Table5[[#This Row],[NODE]]), VPC!A:A, 2, 0), "No está en VPC") | L2: =IF(OR(ISNUMBER(SEARCH("VPC-Leaf", K2)), ISNUMBER(SEARCH("VPC_Leaf", K2))),SUBSTITUTE(SUBSTITUTE(SUBSTITUTE(K2, "VPC-Leaf", ""), "VPC_Leaf", ""), "_", "-"),A2) | M2: =_xlfn.IFNA(VLOOKUP(_xlfn.CONCAT(VALUE(Table5[[#This Row],[NODE]]),Table5[[#This Row],[PORT]]),PG!C:H,6,0),"NO EXISTE PG") | N2: =_xlfn.IFNA(VLOOKUP(_xlfn.CONCAT(VALUE(Table5[[#This Row],[NODE]]),Table5[[#This Row],[PORT]]),PG!C:H,4,0),"NO EXISTE ISEL") | O2: =COUNTIF(Statics!G:G,Table5[[#This Row],[PG]])+COUNTIF(Statics!H:H,_xlfn.CONCAT((Table5[[#This Row],[NODE]]),Table5[[#This Row],[PORT]])) | P2: =_xlfn.IFNA( VLOOKUP(Table5[[#This Row],[PG]], L3OUTS!F:H, 3, 0), _xlfn.IFNA( VLOOKUP(VALUE(Table5[[#This Row],[NODE]]) & Table5[[#This Row],[PORT]], L3OUTS!G:H, 2, 0), _xlfn.IFNA( VLOOKUP(Table5[[#This Row],[PG]], L3OUTS!G:H, 2, 0), "NO TIENE L3OUT" ) ) ) | Q2: =COUNTIF(Statics!F:F,Table5[[#This Row],[ID]])+COUNTIF(Statics!F:F,VALUE(Table5[[#This Row],[NODE]]))
A3: 101 | B3: 1 | C3: =VLOOKUP(VALUE(Table5[[#This Row],[NODE]]),LEAF_INFO!B:H,6,0) | D3: eth1/34 | E3: down | F3: down | G3: =VLOOKUP(_xlfn.CONCAT(Table5[[#This Row],[NODE]],Table5[[#This Row],[PORT]]),PORTS_!A:G,7,0) | I3: =VLOOKUP(VALUE(Table5[[#This Row],[NODE]]),LEAF_INFO!B:H,7,0) | J3: =ISNUMBER(SEARCH("vpc-leaf", SUBSTITUTE(LOWER(K3), "_", "-"))) | K3: =_xlfn.IFNA(VLOOKUP(VALUE(Table5[[#This Row],[NODE]]), VPC!A:A, 2, 0), "No está en VPC") | L3: =IF(OR(ISNUMBER(SEARCH("VPC-Leaf", K3)), ISNUMBER(SEARCH("VPC_Leaf", K3))),SUBSTITUTE(SUBSTITUTE(SUBSTITUTE(K3, "VPC-Leaf", ""), "VPC_Leaf", ""), "_", "-"),A3) | M3: =_xlfn.IFNA(VLOOKUP(_xlfn.CONCAT(VALUE(Table5[[#This Row],[NODE]]),Table5[[#This Row],[PORT]]),PG!C:H,6,0),"NO EXISTE PG") | N3: =_xlfn.IFNA(VLOOKUP(_xlfn.CONCAT(VALUE(Table5[[#This Row],[NODE]]),Table5[[#This Row],[PORT]]),PG!C:H,4,0),"NO EXISTE ISEL") | O3: =COUNTIF(Statics!G:G,Table5[[#This Row],[PG]])+COUNTIF(Statics!H:H,_xlfn.CONCAT((Table5[[#This Row],[NODE]]),Table5[[#This Row],[PORT]])) | P3: =_xlfn.IFNA( VLOOKUP(Table5[[#This Row],[PG]], L3OUTS!F:H, 3, 0), _xlfn.IFNA( VLOOKUP(VALUE(Table5[[#This Row],[NODE]]) & Table5[[#This Row],[PORT]], L3OUTS!G:H, 2, 0), _xlfn.IFNA( VLOOKUP(Table5[[#This Row],[PG]], L3OUTS!G:H, 2, 0), "NO TIENE L3OUT" ) ) ) | Q3: =COUNTIF(Statics!F:F,Table5[[#This Row],[ID]])+COUNTIF(Statics!F:F,VALUE(Table5[[#This Row],[NODE]]))
A4: 101 | B4: 1 | C4: =VLOOKUP(VALUE(Table5[[#This Row],[NODE]]),LEAF_INFO!B:H,6,0) | D4: eth1/35 | E4: down | F4: down | G4: =VLOOKUP(_xlfn.CONCAT(Table5[[#This Row],[NODE]],Table5[[#This Row],[PORT]]),PORTS_!A:G,7,0) | I4: =VLOOKUP(VALUE(Table5[[#This Row],[NODE]]),LEAF_INFO!B:H,7,0) | J4: =ISNUMBER(SEARCH("vpc-leaf", SUBSTITUTE(LOWER(K4), "_", "-"))) | K4: =_xlfn.IFNA(VLOOKUP(VALUE(Table5[[#This Row],[NODE]]), VPC!A:A, 2, 0), "No está en VPC") | L4: =IF(OR(ISNUMBER(SEARCH("VPC-Leaf", K4)), ISNUMBER(SEARCH("VPC_Leaf", K4))),SUBSTITUTE(SUBSTITUTE(SUBSTITUTE(K4, "VPC-Leaf", ""), "VPC_Leaf", ""), "_", "-"),A4) | M4: =_xlfn.IFNA(VLOOKUP(_xlfn.CONCAT(VALUE(Table5[[#This Row],[NODE]]),Table5[[#This Row],[PORT]]),PG!C:H,6,0),"NO EXISTE PG") | N4: =_xlfn.IFNA(VLOOKUP(_xlfn.CONCAT(VALUE(Table5[[#This Row],[NODE]]),Table5[[#This Row],[PORT]]),PG!C:H,4,0),"NO EXISTE ISEL") | O4: =COUNTIF(Statics!G:G,Table5[[#This Row],[PG]])+COUNTIF(Statics!H:H,_xlfn.CONCAT((Table5[[#This Row],[NODE]]),Table5[[#This Row],[PORT]])) | P4: =_xlfn.IFNA( VLOOKUP(Table5[[#This Row],[PG]], L3OUTS!F:H, 3, 0), _xlfn.IFNA( VLOOKUP(VALUE(Table5[[#This Row],[NODE]]) & Table5[[#This Row],[PORT]], L3OUTS!G:H, 2, 0), _xlfn.IFNA( VLOOKUP(Table5[[#This Row],[PG]], L3OUTS!G:H, 2, 0), "NO TIENE L3OUT" ) ) ) | Q4: =COUNTIF(Statics!F:F,Table5[[#This Row],[ID]])+COUNTIF(Statics!F:F,VALUE(Table5[[#This Row],[NODE]]))
A5: 101 | B5: 1 | C5: =VLOOKUP(VALUE(Table5[[#This Row],[NODE]]),LEAF_INFO!B:H,6,0) | D5: eth1/36 | E5: up | F5: up | G5: =VLOOKUP(_xlfn.CONCAT(Table5[[#This Row],[NODE]],Table5[[#This Row],[PORT]]),PORTS_!A:G,7,0) | H5: B2B A SMAC1 | I5: =VLOOKUP(VALUE(Table5[[#This Row],[NODE]]),LEAF_INFO!B:H,7,0) | J5: =ISNUMBER(SEARCH("vpc-leaf", SUBSTITUTE(LOWER(K5), "_", "-"))) | K5: =_xlfn.IFNA(VLOOKUP(VALUE(Table5[[#This Row],[NODE]]), VPC!A:A, 2, 0), "No está en VPC") | L5: =IF(OR(ISNUMBER(SEARCH("VPC-Leaf", K5)), ISNUMBER(SEARCH("VPC_Leaf", K5))),SUBSTITUTE(SUBSTITUTE(SUBSTITUTE(K5, "VPC-Leaf", ""), "VPC_Leaf", ""), "_", "-"),A5) | M5: =_xlfn.IFNA(VLOOKUP(_xlfn.CONCAT(VALUE(Table5[[#This Row],[NODE]]),Table5[[#This Row],[PORT]]),PG!C:H,6,0),"NO EXISTE PG") | N5: =_xlfn.IFNA(VLOOKUP(_xlfn.CONCAT(VALUE(Table5[[#This Row],[NODE]]),Table5[[#This Row],[PORT]]),PG!C:H,4,0),"NO EXISTE ISEL") | O5: =COUNTIF(Statics!G:G,Table5[[#This Row],[PG]])+COUNTIF(Statics!H:H,_xlfn.CONCAT((Table5[[#This Row],[NODE]]),Table5[[#This Row],[PORT]])) | P5: =_xlfn.IFNA( VLOOKUP(Table5[[#This Row],[PG]], L3OUTS!F:H, 3, 0), _xlfn.IFNA( VLOOKUP(VALUE(Table5[[#This Row],[NODE]]) & Table5[[#This Row],[PORT]], L3OUTS!G:H, 2, 0), _xlfn.IFNA( VLOOKUP(Table5[[#This Row],[PG]], L3OUTS!G:H, 2, 0), "NO TIENE L3OUT" ) ) ) | Q5: =COUNTIF(Statics!F:F,Table5[[#This Row],[ID]])+COUNTIF(Statics!F:F,VALUE(Table5[[#This Row],[NODE]]))
A6: 101 | B6: 1 | C6: =VLOOKUP(VALUE(Table5[[#This Row],[NODE]]),LEAF_INFO!B:H,6,0) | D6: eth1/37 | E6: down | F6: down | G6: =VLOOKUP(_xlfn.CONCAT(Table5[[#This Row],[NODE]],Table5[[#This Row],[PORT]]),PORTS_!A:G,7,0) | I6: =VLOOKUP(VALUE(Table5[[#This Row],[NODE]]),LEAF_INFO!B:H,7,0) | J6: =ISNUMBER(SEARCH("vpc-leaf", SUBSTITUTE(LOWER(K6), "_", "-"))) | K6: =_xlfn.IFNA(VLOOKUP(VALUE(Table5[[#This Row],[NODE]]), VPC!A:A, 2, 0), "No está en VPC") | L6: =IF(OR(ISNUMBER(SEARCH("VPC-Leaf", K6)), ISNUMBER(SEARCH("VPC_Leaf", K6))),SUBSTITUTE(SUBSTITUTE(SUBSTITUTE(K6, "VPC-Leaf", ""), "VPC_Leaf", ""), "_", "-"),A6) | M6: =_xlfn.IFNA(VLOOKUP(_xlfn.CONCAT(VALUE(Table5[[#This Row],[NODE]]),Table5[[#This Row],[PORT]]),PG!C:H,6,0),"NO EXISTE PG") | N6: =_xlfn.IFNA(VLOOKUP(_xlfn.CONCAT(VALUE(Table5[[#This Row],[NODE]]),Table5[[#This Row],[PORT]]),PG!C:H,4,0),"NO EXISTE ISEL") | O6: =COUNTIF(Statics!G:G,Table5[[#This Row],[PG]])+COUNTIF(Statics!H:H,_xlfn.CONCAT((Table5[[#This Row],[NODE]]),Table5[[#This Row],[PORT]])) | P6: =_xlfn.IFNA( VLOOKUP(Table5[[#This Row],[PG]], L3OUTS!F:H, 3, 0), _xlfn.IFNA( VLOOKUP(VALUE(Table5[[#This Row],[NODE]]) & Table5[[#This Row],[PORT]], L3OUTS!G:H, 2, 0), _xlfn.IFNA( VLOOKUP(Table5[[#This Row],[PG]], L3OUTS!G:H, 2, 0), "NO TIENE L3OUT" ) ) ) | Q6: =COUNTIF(Statics!F:F,Table5[[#This Row],[ID]])+COUNTIF(Statics!F:F,VALUE(Table5[[#This Row],[NODE]]))
A7: 101 | B7: 1 | C7: =VLOOKUP(VALUE(Table5[[#This Row],[NODE]]),LEAF_INFO!B:H,6,0) | D7: eth1/38 | E7: up | F7: up | G7: =VLOOKUP(_xlfn.CONCAT(Table5[[#This Row],[NODE]],Table5[[#This Row],[PORT]]),PORTS_!A:G,7,0) | H7: HACIA RMAC1 BUNDLE110 | I7: =VLOOKUP(VALUE(Table5[[#This Row],[NODE]]),LEAF_INFO!B:H,7,0) | J7: =ISNUMBER(SEARCH("vpc-leaf", SUBSTITUTE(LOWER(K7), "_", "-"))) | K7: =_xlfn.IFNA(VLOOKUP(VALUE(Table5[[#This Row],[NODE]]), VPC!A:A, 2, 0), "No está en VPC") | L7: =IF(OR(ISNUMBER(SEARCH("VPC-Leaf", K7)), ISNUMBER(SEARCH("VPC_Leaf", K7))),SUBSTITUTE(SUBSTITUTE(SUBSTITUTE(K7, "VPC-Leaf", ""), "VPC_Leaf", ""), "_", "-"),A7) | M7: =_xlfn.IFNA(VLOOKUP(_xlfn.CONCAT(VALUE(Table5[[#This Row],[NODE]]),Table5[[#This Row],[PORT]]),PG!C:H,6,0),"NO EXISTE PG") | N7: =_xlfn.IFNA(VLOOKUP(_xlfn.CONCAT(VALUE(Table5[[#This Row],[NODE]]),Table5[[#This Row],[PORT]]),PG!C:H,4,0),"NO EXISTE ISEL") | O7: =COUNTIF(Statics!G:G,Table5[[#This Row],[PG]])+COUNTIF(Statics!H:H,_xlfn.CONCAT((Table5[[#This Row],[NODE]]),Table5[[#This Row],[PORT]])) | P7: =_xlfn.IFNA( VLOOKUP(Table5[[#This Row],[PG]], L3OUTS!F:H, 3, 0), _xlfn.IFNA( VLOOKUP(VALUE(Table5[[#This Row],[NODE]]) & Table5[[#This Row],[PORT]], L3OUTS!G:H, 2, 0), _xlfn.IFNA( VLOOKUP(Table5[[#This Row],[PG]], L3OUTS!G:H, 2, 0), "NO TIENE L3OUT" ) ) ) | Q7: =COUNTIF(Statics!F:F,Table5[[#This Row],[ID]])+COUNTIF(Statics!F:F,VALUE(Table5[[#This Row],[NODE]]))
A8: 101 | B8: 1 | C8: =VLOOKUP(VALUE(Table5[[#This Row],[NODE]]),LEAF_INFO!B:H,6,0) | D8: eth1/39 | E8: down | F8: down | G8: =VLOOKUP(_xlfn.CONCAT(Table5[[#This Row],[NODE]],Table5[[#This Row],[PORT]]),PORTS_!A:G,7,0) | I8: =VLOOKUP(VALUE(Table5[[#This Row],[NODE]]),LEAF_INFO!B:H,7,0) | J8: =ISNUMBER(SEARCH("vpc-leaf", SUBSTITUTE(LOWER(K8), "_", "-"))) | K8: =_xlfn.IFNA(VLOOKUP(VALUE(Table5[[#This Row],[NODE]]), VPC!A:A, 2, 0), "No está en VPC") | L8: =IF(OR(ISNUMBER(SEARCH("VPC-Leaf", K8)), ISNUMBER(SEARCH("VPC_Leaf", K8))),SUBSTITUTE(SUBSTITUTE(SUBSTITUTE(K8, "VPC-Leaf", ""), "VPC_Leaf", ""), "_", "-"),A8) | M8: =_xlfn.IFNA(VLOOKUP(_xlfn.CONCAT(VALUE(Table5[[#This Row],[NODE]]),Table5[[#This Row],[PORT]]),PG!C:H,6,0),"NO EXISTE PG") | N8: =_xlfn.IFNA(VLOOKUP(_xlfn.CONCAT(VALUE(Table5[[#This Row],[NODE]]),Table5[[#This Row],[PORT]]),PG!C:H,4,0),"NO EXISTE ISEL") | O8: =COUNTIF(Statics!G:G,Table5[[#This Row],[PG]])+COUNTIF(Statics!H:H,_xlfn.CONCAT((Table5[[#This Row],[NODE]]),Table5[[#This Row],[PORT]])) | P8: =_xlfn.IFNA( VLOOKUP(Table5[[#This Row],[PG]], L3OUTS!F:H, 3, 0), _xlfn.IFNA( VLOOKUP(VALUE(Table5[[#This Row],[NODE]]) & Table5[[#This Row],[PORT]], L3OUTS!G:H, 2, 0), _xlfn.IFNA( VLOOKUP(Table5[[#This Row],[PG]], L3OUTS!G:H, 2, 0), "NO TIENE L3OUT" ) ) ) | Q8: =COUNTIF(Statics!F:F,Table5[[#This Row],[ID]])+COUNTIF(Statics!F:F,VALUE(Table5[[#This Row],[NODE]]))
A9: 101 | B9: 1 | C9: =VLOOKUP(VALUE(Table5[[#This Row],[NODE]]),LEAF_INFO!B:H,6,0) | D9: eth1/40 | E9: up | F9: up | G9: =VLOOKUP(_xlfn.CONCAT(Table5[[#This Row],[NODE]],Table5[[#This Row],[PORT]]),PORTS_!A:G,7,0) | H9: A 2R_MAC_MXINGEN_1 | B2B | UP-LINK SERVICIOS | I9: =VLOOKUP(VALUE(Table5[[#This Row],[NODE]]),LEAF_INFO!B:H,7,0) | J9: =ISNUMBER(SEARCH("vpc-leaf", SUBSTITUTE(LOWER(K9), "_", "-"))) | K9: =_xlfn.IFNA(VLOOKUP(VALUE(Table5[[#This Row],[NODE]]), VPC!A:A, 2, 0), "No está en VPC") | L9: =IF(OR(ISNUMBER(SEARCH("VPC-Leaf", K9)), ISNUMBER(SEARCH("VPC_Leaf", K9))),SUBSTITUTE(SUBSTITUTE(SUBSTITUTE(K9, "VPC-Leaf", ""), "VPC_Leaf", ""), "_", "-"),A9) | M9: =_xlfn.IFNA(VLOOKUP(_xlfn.CONCAT(VALUE(Table5[[#This Row],[NODE]]),Table5[[#This Row],[PORT]]),PG!C:H,6,0),"NO EXISTE PG") | N9: =_xlfn.IFNA(VLOOKUP(_xlfn.CONCAT(VALUE(Table5[[#This Row],[NODE]]),Table5[[#This Row],[PORT]]),PG!C:H,4,0),"NO EXISTE ISEL") | O9: =COUNTIF(Statics!G:G,Table5[[#This Row],[PG]])+COUNTIF(Statics!H:H,_xlfn.CONCAT((Table5[[#This Row],[NODE]]),Table5[[#This Row],[PORT]])) | P9: =_xlfn.IFNA( VLOOKUP(Table5[[#This Row],[PG]], L3OUTS!F:H, 3, 0), _xlfn.IFNA( VLOOKUP(VALUE(Table5[[#This Row],[NODE]]) & Table5[[#This Row],[PORT]], L3OUTS!G:H, 2, 0), _xlfn.IFNA( VLOOKUP(Table5[[#This Row],[PG]], L3OUTS!G:H, 2, 0), "NO TIENE L3OUT" ) ) ) | Q9: =COUNTIF(Statics!F:F,Table5[[#This Row],[ID]])+COUNTIF(Statics!F:F,VALUE(Table5[[#This Row],[NODE]]))
A10: 101 | B10: 1 | C10: =VLOOKUP(VALUE(Table5[[#This Row],[NODE]]),LEAF_INFO!B:H,6,0) | D10: eth1/41 | E10: up | F10: up | G10: =VLOOKUP(_xlfn.CONCAT(Table5[[#This Row],[NODE]],Table5[[#This Row],[PORT]]),PORTS_!A:G,7,0) | H10: LINK_GESTION | I10: =VLOOKUP(VALUE(Table5[[#This Row],[NODE]]),LEAF_INFO!B:H,7,0) | J10: =ISNUMBER(SEARCH("vpc-leaf", SUBSTITUTE(LOWER(K10), "_", "-"))) | K10: =_xlfn.IFNA(VLOOKUP(VALUE(Table5[[#This Row],[NODE]]), VPC!A:A, 2, 0), "No está en VPC") | L10: =IF(OR(ISNUMBER(SEARCH("VPC-Leaf", K10)), ISNUMBER(SEARCH("VPC_Leaf", K10))),SUBSTITUTE(SUBSTITUTE(SUBSTITUTE(K10, "VPC-Leaf", ""), "VPC_Leaf", ""), "_", "-"),A10) | M10: =_xlfn.IFNA(VLOOKUP(_xlfn.CONCAT(VALUE(Table5[[#This Row],[NODE]]),Table5[[#This Row],[PORT]]),PG!C:H,6,0),"NO EXISTE PG") | N10: =_xlfn.IFNA(VLOOKUP(_xlfn.CONCAT(VALUE(Table5[[#This Row],[NODE]]),Table5[[#This Row],[PORT]]),PG!C:H,4,0),"NO EXISTE ISEL") | O10: =COUNTIF(Statics!G:G,Table5[[#This Row],[PG]])+COUNTIF(Statics!H:H,_xlfn.CONCAT((Table5[[#This Row],[NODE]]),Table5[[#This Row],[PORT]])) | P10: =_xlfn.IFNA( VLOOKUP(Table5[[#This Row],[PG]], L3OUTS!F:H, 3, 0), _xlfn.IFNA( VLOOKUP(VALUE(Table5[[#This Row],[NODE]]) & Table5[[#This Row],[PORT]], L3OUTS!G:H, 2, 0), _xlfn.IFNA( VLOOKUP(Table5[[#This Row],[PG]], L3OUTS!G:H, 2, 0), "NO TIENE L3OUT" ) ) ) | Q10: =COUNTIF(Statics!F:F,Table5[[#This Row],[ID]])+COUNTIF(Statics!F:F,VALUE(Table5[[#This Row],[NODE]]))
A11: 101 | B11: 1 | C11: =VLOOKUP(VALUE(Table5[[#This Row],[NODE]]),LEAF_INFO!B:H,6,0) | D11: eth1/42 | E11: down | F11: down | G11: =VLOOKUP(_xlfn.CONCAT(Table5[[#This Row],[NODE]],Table5[[#This Row],[PORT]]),PORTS_!A:G,7,0) | I11: =VLOOKUP(VALUE(Table5[[#This Row],[NODE]]),LEAF_INFO!B:H,7,0) | J11: =ISNUMBER(SEARCH("vpc-leaf", SUBSTITUTE(LOWER(K11), "_", "-"))) | K11: =_xlfn.IFNA(VLOOKUP(VALUE(Table5[[#This Row],[NODE]]), VPC!A:A, 2, 0), "No está en VPC") | L11: =IF(OR(ISNUMBER(SEARCH("VPC-Leaf", K11)), ISNUMBER(SEARCH("VPC_Leaf", K11))),SUBSTITUTE(SUBSTITUTE(SUBSTITUTE(K11, "VPC-Leaf", ""), "VPC_Leaf", ""), "_", "-"),A11) | M11: =_xlfn.IFNA(VLOOKUP(_xlfn.CONCAT(VALUE(Table5[[#This Row],[NODE]]),Table5[[#This Row],[PORT]]),PG!C:H,6,0),"NO EXISTE PG") | N11: =_xlfn.IFNA(VLOOKUP(_xlfn.CONCAT(VALUE(Table5[[#This Row],[NODE]]),Table5[[#This Row],[PORT]]),PG!C:H,4,0),"NO EXISTE ISEL") | O11: =COUNTIF(Statics!G:G,Table5[[#This Row],[PG]])+COUNTIF(Statics!H:H,_xlfn.CONCAT((Table5[[#This Row],[NODE]]),Table5[[#This Row],[PORT]])) | P11: =_xlfn.IFNA( VLOOKUP(Table5[[#This Row],[PG]], L3OUTS!F:H, 3, 0), _xlfn.IFNA( VLOOKUP(VALUE(Table5[[#This Row],[NODE]]) & Table5[[#This Row],[PORT]], L3OUTS!G:H, 2, 0), _xlfn.IFNA( VLOOKUP(Table5[[#This Row],[PG]], L3OUTS!G:H, 2, 0), "NO TIENE L3OUT" ) ) ) | Q11: =COUNTIF(Statics!F:F,Table5[[#This Row],[ID]])+COUNTIF(Statics!F:F,VALUE(Table5[[#This Row],[NODE]]))
A12: 101 | B12: 1 | C12: =VLOOKUP(VALUE(Table5[[#This Row],[NODE]]),LEAF_INFO!B:H,6,0) | D12: eth1/43 | E12: down | F12: down | G12: =VLOOKUP(_xlfn.CONCAT(Table5[[#This Row],[NODE]],Table5[[#This Row],[PORT]]),PORTS_!A:G,7,0) | I12: =VLOOKUP(VALUE(Table5[[#This Row],[NODE]]),LEAF_INFO!B:H,7,0) | J12: =ISNUMBER(SEARCH("vpc-leaf", SUBSTITUTE(LOWER(K12), "_", "-"))) | K12: =_xlfn.IFNA(VLOOKUP(VALUE(Table5[[#This Row],[NODE]]), VPC!A:A, 2, 0), "No está en VPC") | L12: =IF(OR(ISNUMBER(SEARCH("VPC-Leaf", K12)), ISNUMBER(SEARCH("VPC_Leaf", K12))),SUBSTITUTE(SUBSTITUTE(SUBSTITUTE(K12, "VPC-Leaf", ""), "VPC_Leaf", ""), "_", "-"),A12) | M12: =_xlfn.IFNA(VLOOKUP(_xlfn.CONCAT(VALUE(Table5[[#This Row],[NODE]]),Table5[[#This Row],[PORT]]),PG!C:H,6,0),"NO EXISTE PG") | N12: =_xlfn.IFNA(VLOOKUP(_xlfn.CONCAT(VALUE(Table5[[#This Row],[NODE]]),Table5[[#This Row],[PORT]]),PG!C:H,4,0),"NO EXISTE ISEL") | O12: =COUNTIF(Statics!G:G,Table5[[#This Row],[PG]])+COUNTIF(Statics!H:H,_xlfn.CONCAT((Table5[[#This Row],[NODE]]),Table5[[#This Row],[PORT]])) | P12: =_xlfn.IFNA( VLOOKUP(Table5[[#This Row],[PG]], L3OUTS!F:H, 3, 0), _xlfn.IFNA( VLOOKUP(VALUE(Table5[[#This Row],[NODE]]) & Table5[[#This Row],[PORT]], L3OUTS!G:H, 2, 0), _xlfn.IFNA( VLOOKUP(Table5[[#This Row],[PG]], L3OUTS!G:H, 2, 0), "NO TIENE L3OUT" ) ) ) | Q12: =COUNTIF(Statics!F:F,Table5[[#This Row],[ID]])+COUNTIF(Statics!F:F,VALUE(Table5[[#This Row],[NODE]]))
A13: 101 | B13: 1 | C13: =VLOOKUP(VALUE(Table5[[#This Row],[NODE]]),LEAF_INFO!B:H,6,0) | D13: eth1/44 | E13: down | F13: down | G13: =VLOOKUP(_xlfn.CONCAT(Table5[[#This Row],[NODE]],Table5[[#This Row],[PORT]]),PORTS_!A:G,7,0) | I13: =VLOOKUP(VALUE(Table5[[#This Row],[NODE]]),LEAF_INFO!B:H,7,0) | J13: =ISNUMBER(SEARCH("vpc-leaf", SUBSTITUTE(LOWER(K13), "_", "-"))) | K13: =_xlfn.IFNA(VLOOKUP(VALUE(Table5[[#This Row],[NODE]]), VPC!A:A, 2, 0), "No está en VPC") | L13: =IF(OR(ISNUMBER(SEARCH("VPC-Leaf", K13)), ISNUMBER(SEARCH("VPC_Leaf", K13))),SUBSTITUTE(SUBSTITUTE(SUBSTITUTE(K13, "VPC-Leaf", ""), "VPC_Leaf", ""), "_", "-"),A13) | M13: =_xlfn.IFNA(VLOOKUP(_xlfn.CONCAT(VALUE(Table5[[#This Row],[NODE]]),Table5[[#This Row],[PORT]]),PG!C:H,6,0),"NO EXISTE PG") | N13: =_xlfn.IFNA(VLOOKUP(_xlfn.CONCAT(VALUE(Table5[[#This Row],[NODE]]),Table5[[#This Row],[PORT]]),PG!C:H,4,0),"NO EXISTE ISEL") | O13: =COUNTIF(Statics!G:G,Table5[[#This Row],[PG]])+COUNTIF(Statics!H:H,_xlfn.CONCAT((Table5[[#This Row],[NODE]]),Table5[[#This Row],[PORT]])) | P13: =_xlfn.IFNA( VLOOKUP(Table5[[#This Row],[PG]], L3OUTS!F:H, 3, 0), _xlfn.IFNA( VLOOKUP(VALUE(Table5[[#This Row],[NODE]]) & Table5[[#This Row],[PORT]], L3OUTS!G:H, 2, 0), _xlfn.IFNA( VLOOKUP(Table5[[#This Row],[PG]], L3OUTS!G:H, 2, 0), "NO TIENE L3OUT" ) ) ) | Q13: =COUNTIF(Statics!F:F,Table5[[#This Row],[ID]])+COUNTIF(Statics!F:F,VALUE(Table5[[#This Row],[NODE]]))
A14: 101 | B14: 1 | C14: =VLOOKUP(VALUE(Table5[[#This Row],[NODE]]),LEAF_INFO!B:H,6,0) | D14: eth1/45 | E14: up | F14: up | G14: =VLOOKUP(_xlfn.CONCAT(Table5[[#This Row],[NODE]],Table5[[#This Row],[PORT]]),PORTS_!A:G,7,0) | H14: HACIA RMAC1 BUNDLE110 | I14: =VLOOKUP(VALUE(Table5[[#This Row],[NODE]]),LEAF_INFO!B:H,7,0) | J14: =ISNUMBER(SEARCH("vpc-leaf", SUBSTITUTE(LOWER(K14), "_", "-"))) | K14: =_xlfn.IFNA(VLOOKUP(VALUE(Table5[[#This Row],[NODE]]), VPC!A:A, 2, 0), "No está en VPC") | L14: =IF(OR(ISNUMBER(SEARCH("VPC-Leaf", K14)), ISNUMBER(SEARCH("VPC_Leaf", K14))),SUBSTITUTE(SUBSTITUTE(SUBSTITUTE(K14, "VPC-Leaf", ""), "VPC_Leaf", ""), "_", "-"),A14) | M14: =_xlfn.IFNA(VLOOKUP(_xlfn.CONCAT(VALUE(Table5[[#This Row],[NODE]]),Table5[[#This Row],[PORT]]),PG!C:H,6,0),"NO EXISTE PG") | N14: =_xlfn.IFNA(VLOOKUP(_xlfn.CONCAT(VALUE(Table5[[#This Row],[NODE]]),Table5[[#This Row],[PORT]]),PG!C:H,4,0),"NO EXISTE ISEL") | O14: =COUNTIF(Statics!G:G,Table5[[#This Row],[PG]])+COUNTIF(Statics!H:H,_xlfn.CONCAT((Table5[[#This Row],[NODE]]),Table5[[#This Row],[PORT]])) | P14: =_xlfn.IFNA( VLOOKUP(Table5[[#This Row],[PG]], L3OUTS!F:H, 3, 0), _xlfn.IFNA( VLOOKUP(VALUE(Table5[[#This Row],[NODE]]) & Table5[[#This Row],[PORT]], L3OUTS!G:H, 2, 0), _xlfn.IFNA( VLOOKUP(Table5[[#This Row],[PG]], L3OUTS!G:H, 2, 0), "NO TIENE L3OUT" ) ) ) | Q14: =COUNTIF(Statics!F:F,Table5[[#This Row],[ID]])+COUNTIF(Statics!F:F,VALUE(Table5[[#This Row],[NODE]]))
A15: 101 | B15: 1 | C15: =VLOOKUP(VALUE(Table5[[#This Row],[NODE]]),LEAF_INFO!B:H,6,0) | D15: eth1/46 | E15: up | F15: up | G15: =VLOOKUP(_xlfn.CONCAT(Table5[[#This Row],[NODE]],Table5[[#This Row],[PORT]]),PORTS_!A:G,7,0) | H15: LINK_HACIA_APIC | I15: =VLOOKUP(VALUE(Table5[[#This Row],[NODE]]),LEAF_INFO!B:H,7,0) | J15: =ISNUMBER(SEARCH("vpc-leaf", SUBSTITUTE(LOWER(K15), "_", "-"))) | K15: =_xlfn.IFNA(VLOOKUP(VALUE(Table5[[#This Row],[NODE]]), VPC!A:A, 2, 0), "No está en VPC") | L15: =IF(OR(ISNUMBER(SEARCH("VPC-Leaf", K15)), ISNUMBER(SEARCH("VPC_Leaf", K15))),SUBSTITUTE(SUBSTITUTE(SUBSTITUTE(K15, "VPC-Leaf", ""), "VPC_Leaf", ""), "_", "-"),A15) | M15: =_xlfn.IFNA(VLOOKUP(_xlfn.CONCAT(VALUE(Table5[[#This Row],[NODE]]),Table5[[#This Row],[PORT]]),PG!C:H,6,0),"NO EXISTE PG") | N15: =_xlfn.IFNA(VLOOKUP(_xlfn.CONCAT(VALUE(Table5[[#This Row],[NODE]]),Table5[[#This Row],[PORT]]),PG!C:H,4,0),"NO EXISTE ISEL") | O15: =COUNTIF(Statics!G:G,Table5[[#This Row],[PG]])+COUNTIF(Statics!H:H,_xlfn.CONCAT((Table5[[#This Row],[NODE]]),Table5[[#This Row],[PORT]])) | P15: =_xlfn.IFNA( VLOOKUP(Table5[[#This Row],[PG]], L3OUTS!F:H, 3, 0), _xlfn.IFNA( VLOOKUP(VALUE(Table5[[#This Row],[NODE]]) & Table5[[#This Row],[PORT]], L3OUTS!G:H, 2, 0), _xlfn.IFNA( VLOOKUP(Table5[[#This Row],[PG]], L3OUTS!G:H, 2, 0), "NO TIENE L3OUT" ) ) ) | Q15: =COUNTIF(Statics!F:F,Table5[[#This Row],[ID]])+COUNTIF(Statics!F:F,VALUE(Table5[[#This Row],[NODE]]))
A16: 101 | B16: 1 | C16: =VLOOKUP(VALUE(Table5[[#This Row],[NODE]]),LEAF_INFO!B:H,6,0) | D16: eth1/47 | E16: up | F16: up | G16: =VLOOKUP(_xlfn.CONCAT(Table5[[#This Row],[NODE]],Table5[[#This Row],[PORT]]),PORTS_!A:G,7,0) | H16: LINK_HACIA_APIC | I16: =VLOOKUP(VALUE(Table5[[#This Row],[NODE]]),LEAF_INFO!B:H,7,0) | J16: =ISNUMBER(SEARCH("vpc-leaf", SUBSTITUTE(LOWER(K16), "_", "-"))) | K16: =_xlfn.IFNA(VLOOKUP(VALUE(Table5[[#This Row],[NODE]]), VPC!A:A, 2, 0), "No está en VPC") | L16: =IF(OR(ISNUMBER(SEARCH("VPC-Leaf", K16)), ISNUMBER(SEARCH("VPC_Leaf", K16))),SUBSTITUTE(SUBSTITUTE(SUBSTITUTE(K16, "VPC-Leaf", ""), "VPC_Leaf", ""), "_", "-"),A16) | M16: =_xlfn.IFNA(VLOOKUP(_xlfn.CONCAT(VALUE(Table5[[#This Row],[NODE]]),Table5[[#This Row],[PORT]]),PG!C:H,6,0),"NO EXISTE PG") | N16: =_xlfn.IFNA(VLOOKUP(_xlfn.CONCAT(VALUE(Table5[[#This Row],[NODE]]),Table5[[#This Row],[PORT]]),PG!C:H,4,0),"NO EXISTE ISEL") | O16: =COUNTIF(Statics!G:G,Table5[[#This Row],[PG]])+COUNTIF(Statics!H:H,_xlfn.CONCAT((Table5[[#This Row],[NODE]]),Table5[[#This Row],[PORT]])) | P16: =_xlfn.IFNA( VLOOKUP(Table5[[#This Row],[PG]], L3OUTS!F:H, 3, 0), _xlfn.IFNA( VLOOKUP(VALUE(Table5[[#This Row],[NODE]]) & Table5[[#This Row],[PORT]], L3OUTS!G:H, 2, 0), _xlfn.IFNA( VLOOKUP(Table5[[#This Row],[PG]], L3OUTS!G:H, 2, 0), "NO TIENE L3OUT" ) ) ) | Q16: =COUNTIF(Statics!F:F,Table5[[#This Row],[ID]])+COUNTIF(Statics!F:F,VALUE(Table5[[#This Row],[NODE]]))
A17: 101 | B17: 1 | C17: =VLOOKUP(VALUE(Table5[[#This Row],[NODE]]),LEAF_INFO!B:H,6,0) | D17: eth1/48 | E17: up | F17: up | G17: =VLOOKUP(_xlfn.CONCAT(Table5[[#This Row],[NODE]],Table5[[#This Row],[PORT]]),PORTS_!A:G,7,0) | H17: LINK_HACIA_APIC | I17: =VLOOKUP(VALUE(Table5[[#This Row],[NODE]]),LEAF_INFO!B:H,7,0) | J17: =ISNUMBER(SEARCH("vpc-leaf", SUBSTITUTE(LOWER(K17), "_", "-"))) | K17: =_xlfn.IFNA(VLOOKUP(VALUE(Table5[[#This Row],[NODE]]), VPC!A:A, 2, 0), "No está en VPC") | L17: =IF(OR(ISNUMBER(SEARCH("VPC-Leaf", K17)), ISNUMBER(SEARCH("VPC_Leaf", K17))),SUBSTITUTE(SUBSTITUTE(SUBSTITUTE(K17, "VPC-Leaf", ""), "VPC_Leaf", ""), "_", "-"),A17) | M17: =_xlfn.IFNA(VLOOKUP(_xlfn.CONCAT(VALUE(Table5[[#This Row],[NODE]]),Table5[[#This Row],[PORT]]),PG!C:H,6,0),"NO EXISTE PG") | N17: =_xlfn.IFNA(VLOOKUP(_xlfn.CONCAT(VALUE(Table5[[#This Row],[NODE]]),Table5[[#This Row],[PORT]]),PG!C:H,4,0),"NO EXISTE ISEL") | O17: =COUNTIF(Statics!G:G,Table5[[#This Row],[PG]])+COUNTIF(Statics!H:H,_xlfn.CONCAT((Table5[[#This Row],[NODE]]),Table5[[#This Row],[PORT]])) | P17: =_xlfn.IFNA( VLOOKUP(Table5[[#This Row],[PG]], L3OUTS!F:H, 3, 0), _xlfn.IFNA( VLOOKUP(VALUE(Table5[[#This Row],[NODE]]) & Table5[[#This Row],[PORT]], L3OUTS!G:H, 2, 0), _xlfn.IFNA( VLOOKUP(Table5[[#This Row],[PG]], L3OUTS!G:H, 2, 0), "NO TIENE L3OUT" ) ) ) | Q17: =COUNTIF(Statics!F:F,Table5[[#This Row],[ID]])+COUNTIF(Statics!F:F,VALUE(Table5[[#This Row],[NODE]]))
A18: 101 | B18: 1 | C18: =VLOOKUP(VALUE(Table5[[#This Row],[NODE]]),LEAF_INFO!B:H,6,0) | D18: eth1/49 | E18: down | F18: down | G18: =VLOOKUP(_xlfn.CONCAT(Table5[[#This Row],[NODE]],Table5[[#This Row],[PORT]]),PORTS_!A:G,7,0) | I18: =VLOOKUP(VALUE(Table5[[#This Row],[NODE]]),LEAF_INFO!B:H,7,0) | J18: =ISNUMBER(SEARCH("vpc-leaf", SUBSTITUTE(LOWER(K18), "_", "-"))) | K18: =_xlfn.IFNA(VLOOKUP(VALUE(Table5[[#This Row],[NODE]]), VPC!A:A, 2, 0), "No está en VPC") | L18: =IF(OR(ISNUMBER(SEARCH("VPC-Leaf", K18)), ISNUMBER(SEARCH("VPC_Leaf", K18))),SUBSTITUTE(SUBSTITUTE(SUBSTITUTE(K18, "VPC-Leaf", ""), "VPC_Leaf", ""), "_", "-"),A18) | M18: =_xlfn.IFNA(VLOOKUP(_xlfn.CONCAT(VALUE(Table5[[#This Row],[NODE]]),Table5[[#This Row],[PORT]]),PG!C:H,6,0),"NO EXISTE PG") | N18: =_xlfn.IFNA(VLOOKUP(_xlfn.CONCAT(VALUE(Table5[[#This Row],[NODE]]),Table5[[#This Row],[PORT]]),PG!C:H,4,0),"NO EXISTE ISEL") | O18: =COUNTIF(Statics!G:G,Table5[[#This Row],[PG]])+COUNTIF(Statics!H:H,_xlfn.CONCAT((Table5[[#This Row],[NODE]]),Table5[[#This Row],[PORT]])) | P18: =_xlfn.IFNA( VLOOKUP(Table5[[#This Row],[PG]], L3OUTS!F:H, 3, 0), _xlfn.IFNA( VLOOKUP(VALUE(Table5[[#This Row],[NODE]]) & Table5[[#This Row],[PORT]], L3OUTS!G:H, 2, 0), _xlfn.IFNA( VLOOKUP(Table5[[#This Row],[PG]], L3OUTS!G:H, 2, 0), "NO TIENE L3OUT" ) ) ) | Q18: =COUNTIF(Statics!F:F,Table5[[#This Row],[ID]])+COUNTIF(Statics!F:F,VALUE(Table5[[#This Row],[NODE]]))
A19: 101 | B19: 1 | C19: =VLOOKUP(VALUE(Table5[[#This Row],[NODE]]),LEAF_INFO!B:H,6,0) | D19: eth1/50 | E19: down | F19: down | G19: =VLOOKUP(_xlfn.CONCAT(Table5[[#This Row],[NODE]],Table5[[#This Row],[PORT]]),PORTS_!A:G,7,0) | I19: =VLOOKUP(VALUE(Table5[[#This Row],[NODE]]),LEAF_INFO!B:H,7,0) | J19: =ISNUMBER(SEARCH("vpc-leaf", SUBSTITUTE(LOWER(K19), "_", "-"))) | K19: =_xlfn.IFNA(VLOOKUP(VALUE(Table5[[#This Row],[NODE]]), VPC!A:A, 2, 0), "No está en VPC") | L19: =IF(OR(ISNUMBER(SEARCH("VPC-Leaf", K19)), ISNUMBER(SEARCH("VPC_Leaf", K19))),SUBSTITUTE(SUBSTITUTE(SUBSTITUTE(K19, "VPC-Leaf", ""), "VPC_Leaf", ""), "_", "-"),A19) | M19: =_xlfn.IFNA(VLOOKUP(_xlfn.CONCAT(VALUE(Table5[[#This Row],[NODE]]),Table5[[#This Row],[PORT]]),PG!C:H,6,0),"NO EXISTE PG") | N19: =_xlfn.IFNA(VLOOKUP(_xlfn.CONCAT(VALUE(Table5[[#This Row],[NODE]]),Table5[[#This Row],[PORT]]),PG!C:H,4,0),"NO EXISTE ISEL") | O19: =COUNTIF(Statics!G:G,Table5[[#This Row],[PG]])+COUNTIF(Statics!H:H,_xlfn.CONCAT((Table5[[#This Row],[NODE]]),Table5[[#This Row],[PORT]])) | P19: =_xlfn.IFNA( VLOOKUP(Table5[[#This Row],[PG]], L3OUTS!F:H, 3, 0), _xlfn.IFNA( VLOOKUP(VALUE(Table5[[#This Row],[NODE]]) & Table5[[#This Row],[PORT]], L3OUTS!G:H, 2, 0), _xlfn.IFNA( VLOOKUP(Table5[[#This Row],[PG]], L3OUTS!G:H, 2, 0), "NO TIENE L3OUT" ) ) ) | Q19: =COUNTIF(Statics!F:F,Table5[[#This Row],[ID]])+COUNTIF(Statics!F:F,VALUE(Table5[[#This Row],[NODE]]))
A20: 101 | B20: 1 | C20: =VLOOKUP(VALUE(Table5[[#This Row],[NODE]]),LEAF_INFO!B:H,6,0) | D20: eth1/51 | E20: down | F20: down | G20: =VLOOKUP(_xlfn.CONCAT(Table5[[#This Row],[NODE]],Table5[[#This Row],[PORT]]),PORTS_!A:G,7,0) | I20: =VLOOKUP(VALUE(Table5[[#This Row],[NODE]]),LEAF_INFO!B:H,7,0) | J20: =ISNUMBER(SEARCH("vpc-leaf", SUBSTITUTE(LOWER(K20), "_", "-"))) | K20: =_xlfn.IFNA(VLOOKUP(VALUE(Table5[[#This Row],[NODE]]), VPC!A:A, 2, 0), "No está en VPC") | L20: =IF(OR(ISNUMBER(SEARCH("VPC-Leaf", K20)), ISNUMBER(SEARCH("VPC_Leaf", K20))),SUBSTITUTE(SUBSTITUTE(SUBSTITUTE(K20, "VPC-Leaf", ""), "VPC_Leaf", ""), "_", "-"),A20) | M20: =_xlfn.IFNA(VLOOKUP(_xlfn.CONCAT(VALUE(Table5[[#This Row],[NODE]]),Table5[[#This Row],[PORT]]),PG!C:H,6,0),"NO EXISTE PG") | N20: =_xlfn.IFNA(VLOOKUP(_xlfn.CONCAT(VALUE(Table5[[#This Row],[NODE]]),Table5[[#This Row],[PORT]]),PG!C:H,4,0),"NO EXISTE ISEL") | O20: =COUNTIF(Statics!G:G,Table5[[#This Row],[PG]])+COUNTIF(Statics!H:H,_xlfn.CONCAT((Table5[[#This Row],[NODE]]),Table5[[#This Row],[PORT]])) | P20: =_xlfn.IFNA( VLOOKUP(Table5[[#This Row],[PG]], L3OUTS!F:H, 3, 0), _xlfn.IFNA( VLOOKUP(VALUE(Table5[[#This Row],[NODE]]) & Table5[[#This Row],[PORT]], L3OUTS!G:H, 2, 0), _xlfn.IFNA( VLOOKUP(Table5[[#This Row],[PG]], L3OUTS!G:H, 2, 0), "NO TIENE L3OUT" ) ) ) | Q20: =COUNTIF(Statics!F:F,Table5[[#This Row],[ID]])+COUNTIF(Statics!F:F,VALUE(Table5[[#This Row],[NODE]]))
A21: 101 | B21: 1 | C21: =VLOOKUP(VALUE(Table5[[#This Row],[NODE]]),LEAF_INFO!B:H,6,0) | D21: eth1/52 | E21: down | F21: down | G21: =VLOOKUP(_xlfn.CONCAT(Table5[[#This Row],[NODE]],Table5[[#This Row],[PORT]]),PORTS_!A:G,7,0) | I21: =VLOOKUP(VALUE(Table5[[#This Row],[NODE]]),LEAF_INFO!B:H,7,0) | J21: =ISNUMBER(SEARCH("vpc-leaf", SUBSTITUTE(LOWER(K21), "_", "-"))) | K21: =_xlfn.IFNA(VLOOKUP(VALUE(Table5[[#This Row],[NODE]]), VPC!A:A, 2, 0), "No está en VPC") | L21: =IF(OR(ISNUMBER(SEARCH("VPC-Leaf", K21)), ISNUMBER(SEARCH("VPC_Leaf", K21))),SUBSTITUTE(SUBSTITUTE(SUBSTITUTE(K21, "VPC-Leaf", ""), "VPC_Leaf", ""), "_", "-"),A21) | M21: =_xlfn.IFNA(VLOOKUP(_xlfn.CONCAT(VALUE(Table5[[#This Row],[NODE]]),Table5[[#This Row],[PORT]]),PG!C:H,6,0),"NO EXISTE PG") | N21: =_xlfn.IFNA(VLOOKUP(_xlfn.CONCAT(VALUE(Table5[[#This Row],[NODE]]),Table5[[#This Row],[PORT]]),PG!C:H,4,0),"NO EXISTE ISEL") | O21: =COUNTIF(Statics!G:G,Table5[[#This Row],[PG]])+COUNTIF(Statics!H:H,_xlfn.CONCAT((Table5[[#This Row],[NODE]]),Table5[[#This Row],[PORT]])) | P21: =_xlfn.IFNA( VLOOKUP(Table5[[#This Row],[PG]], L3OUTS!F:H, 3, 0), _xlfn.IFNA( VLOOKUP(VALUE(Table5[[#This Row],[NODE]]) & Table5[[#This Row],[PORT]], L3OUTS!G:H, 2, 0), _xlfn.IFNA( VLOOKUP(Table5[[#This Row],[PG]], L3OUTS!G:H, 2, 0), "NO TIENE L3OUT" ) ) ) | Q21: =COUNTIF(Statics!F:F,Table5[[#This Row],[ID]])+COUNTIF(Statics!F:F,VALUE(Table5[[#This Row],[NODE]]))
A22: 101 | B22: 1 | C22: =VLOOKUP(VALUE(Table5[[#This Row],[NODE]]),LEAF_INFO!B:H,6,0) | D22: eth1/53 | E22: up | F22: up | G22: =VLOOKUP(_xlfn.CONCAT(Table5[[#This Row],[NODE]],Table5[[#This Row],[PORT]]),PORTS_!A:G,7,0) | H22: LINK_HACIA_SPINE | I22: =VLOOKUP(VALUE(Table5[[#This Row],[NODE]]),LEAF_INFO!B:H,7,0) | J22: =ISNUMBER(SEARCH("vpc-leaf", SUBSTITUTE(LOWER(K22), "_", "-"))) | K22: =_xlfn.IFNA(VLOOKUP(VALUE(Table5[[#This Row],[NODE]]), VPC!A:A, 2, 0), "No está en VPC") | L22: =IF(OR(ISNUMBER(SEARCH("VPC-Leaf", K22)), ISNUMBER(SEARCH("VPC_Leaf", K22))),SUBSTITUTE(SUBSTITUTE(SUBSTITUTE(K22, "VPC-Leaf", ""), "VPC_Leaf", ""), "_", "-"),A22) | M22: =_xlfn.IFNA(VLOOKUP(_xlfn.CONCAT(VALUE(Table5[[#This Row],[NODE]]),Table5[[#This Row],[PORT]]),PG!C:H,6,0),"NO EXISTE PG") | N22: =_xlfn.IFNA(VLOOKUP(_xlfn.CONCAT(VALUE(Table5[[#This Row],[NODE]]),Table5[[#This Row],[PORT]]),PG!C:H,4,0),"NO EXISTE ISEL") | O22: =COUNTIF(Statics!G:G,Table5[[#This Row],[PG]])+COUNTIF(Statics!H:H,_xlfn.CONCAT((Table5[[#This Row],[NODE]]),Table5[[#This Row],[PORT]])) | P22: =_xlfn.IFNA( VLOOKUP(Table5[[#This Row],[PG]], L3OUTS!F:H, 3, 0), _xlfn.IFNA( VLOOKUP(VALUE(Table5[[#This Row],[NODE]]) & Table5[[#This Row],[PORT]], L3OUTS!G:H, 2, 0), _xlfn.IFNA( VLOOKUP(Table5[[#This Row],[PG]], L3OUTS!G:H, 2, 0), "NO TIENE L3OUT" ) ) ) | Q22: =COUNTIF(Statics!F:F,Table5[[#This Row],[ID]])+COUNTIF(Statics!F:F,VALUE(Table5[[#This Row],[NODE]]))
A23: 101 | B23: 1 | C23: =VLOOKUP(VALUE(Table5[[#This Row],[NODE]]),LEAF_INFO!B:H,6,0) | D23: eth1/54 | E23: up | F23: up | G23: =VLOOKUP(_xlfn.CONCAT(Table5[[#This Row],[NODE]],Table5[[#This Row],[PORT]]),PORTS_!A:G,7,0) | H23: LINK_HACIA_SPINE | I23: =VLOOKUP(VALUE(Table5[[#This Row],[NODE]]),LEAF_INFO!B:H,7,0) | J23: =ISNUMBER(SEARCH("vpc-leaf", SUBSTITUTE(LOWER(K23), "_", "-"))) | K23: =_xlfn.IFNA(VLOOKUP(VALUE(Table5[[#This Row],[NODE]]), VPC!A:A, 2, 0), "No está en VPC") | L23: =IF(OR(ISNUMBER(SEARCH("VPC-Leaf", K23)), ISNUMBER(SEARCH("VPC_Leaf", K23))),SUBSTITUTE(SUBSTITUTE(SUBSTITUTE(K23, "VPC-Leaf", ""), "VPC_Leaf", ""), "_", "-"),A23) | M23: =_xlfn.IFNA(VLOOKUP(_xlfn.CONCAT(VALUE(Table5[[#This Row],[NODE]]),Table5[[#This Row],[PORT]]),PG!C:H,6,0),"NO EXISTE PG") | N23: =_xlfn.IFNA(VLOOKUP(_xlfn.CONCAT(VALUE(Table5[[#This Row],[NODE]]),Table5[[#This Row],[PORT]]),PG!C:H,4,0),"NO EXISTE ISEL") | O23: =COUNTIF(Statics!G:G,Table5[[#This Row],[PG]])+COUNTIF(Statics!H:H,_xlfn.CONCAT((Table5[[#This Row],[NODE]]),Table5[[#This Row],[PORT]])) | P23: =_xlfn.IFNA( VLOOKUP(Table5[[#This Row],[PG]], L3OUTS!F:H, 3, 0), _xlfn.IFNA( VLOOKUP(VALUE(Table5[[#This Row],[NODE]]) & Table5[[#This Row],[PORT]], L3OUTS!G:H, 2, 0), _xlfn.IFNA( VLOOKUP(Table5[[#This Row],[PG]], L3OUTS!G:H, 2, 0), "NO TIENE L3OUT" ) ) ) | Q23: =COUNTIF(Statics!F:F,Table5[[#This Row],[ID]])+COUNTIF(Statics!F:F,VALUE(Table5[[#This Row],[NODE]]))
A24: 101 | B24: 1 | C24: =VLOOKUP(VALUE(Table5[[#This Row],[NODE]]),LEAF_INFO!B:H,6,0) | D24: eth1/1 | E24: down | F24: down | G24: =VLOOKUP(_xlfn.CONCAT(Table5[[#This Row],[NODE]],Table5[[#This Row],[PORT]]),PORTS_!A:G,7,0) | I24: =VLOOKUP(VALUE(Table5[[#This Row],[NODE]]),LEAF_INFO!B:H,7,0) | J24: =ISNUMBER(SEARCH("vpc-leaf", SUBSTITUTE(LOWER(K24), "_", "-"))) | K24: =_xlfn.IFNA(VLOOKUP(VALUE(Table5[[#This Row],[NODE]]), VPC!A:A, 2, 0), "No está en VPC") | L24: =IF(OR(ISNUMBER(SEARCH("VPC-Leaf", K24)), ISNUMBER(SEARCH("VPC_Leaf", K24))),SUBSTITUTE(SUBSTITUTE(SUBSTITUTE(K24, "VPC-Leaf", ""), "VPC_Leaf", ""), "_", "-"),A24) | M24: =_xlfn.IFNA(VLOOKUP(_xlfn.CONCAT(VALUE(Table5[[#This Row],[NODE]]),Table5[[#This Row],[PORT]]),PG!C:H,6,0),"NO EXISTE PG") | N24: =_xlfn.IFNA(VLOOKUP(_xlfn.CONCAT(VALUE(Table5[[#This Row],[NODE]]),Table5[[#This Row],[PORT]]),PG!C:H,4,0),"NO EXISTE ISEL") | O24: =COUNTIF(Statics!G:G,Table5[[#This Row],[PG]])+COUNTIF(Statics!H:H,_xlfn.CONCAT((Table5[[#This Row],[NODE]]),Table5[[#This Row],[PORT]])) | P24: =_xlfn.IFNA( VLOOKUP(Table5[[#This Row],[PG]], L3OUTS!F:H, 3, 0), _xlfn.IFNA( VLOOKUP(VALUE(Table5[[#This Row],[NODE]]) & Table5[[#This Row],[PORT]], L3OUTS!G:H, 2, 0), _xlfn.IFNA( VLOOKUP(Table5[[#This Row],[PG]], L3OUTS!G:H, 2, 0), "NO TIENE L3OUT" ) ) ) | Q24: =COUNTIF(Statics!F:F,Table5[[#This Row],[ID]])+COUNTIF(Statics!F:F,VALUE(Table5[[#This Row],[NODE]]))
A25: 101 | B25: 1 | C25: =VLOOKUP(VALUE(Table5[[#This Row],[NODE]]),LEAF_INFO!B:H,6,0) | D25: eth1/2 | E25: down | F25: down | G25: =VLOOKUP(_xlfn.CONCAT(Table5[[#This Row],[NODE]],Table5[[#This Row],[PORT]]),PORTS_!A:G,7,0) | I25: =VLOOKUP(VALUE(Table5[[#This Row],[NODE]]),LEAF_INFO!B:H,7,0) | J25: =ISNUMBER(SEARCH("vpc-leaf", SUBSTITUTE(LOWER(K25), "_", "-"))) | K25: =_xlfn.IFNA(VLOOKUP(VALUE(Table5[[#This Row],[NODE]]), VPC!A:A, 2, 0), "No está en VPC") | L25: =IF(OR(ISNUMBER(SEARCH("VPC-Leaf", K25)), ISNUMBER(SEARCH("VPC_Leaf", K25))),SUBSTITUTE(SUBSTITUTE(SUBSTITUTE(K25, "VPC-Leaf", ""), "VPC_Leaf", ""), "_", "-"),A25) | M25: =_xlfn.IFNA(VLOOKUP(_xlfn.CONCAT(VALUE(Table5[[#This Row],[NODE]]),Table5[[#This Row],[PORT]]),PG!C:H,6,0),"NO EXISTE PG") | N25: =_xlfn.IFNA(VLOOKUP(_xlfn.CONCAT(VALUE(Table5[[#This Row],[NODE]]),Table5[[#This Row],[PORT]]),PG!C:H,4,0),"NO EXISTE ISEL") | O25: =COUNTIF(Statics!G:G,Table5[[#This Row],[PG]])+COUNTIF(Statics!H:H,_xlfn.CONCAT((Table5[[#This Row],[NODE]]),Table5[[#This Row],[PORT]])) | P25: =_xlfn.IFNA( VLOOKUP(Table5[[#This Row],[PG]], L3OUTS!F:H, 3, 0), _xlfn.IFNA( VLOOKUP(VALUE(Table5[[#This Row],[NODE]]) & Table5[[#This Row],[PORT]], L3OUTS!G:H, 2, 0), _xlfn.IFNA( VLOOKUP(Table5[[#This Row],[PG]], L3OUTS!G:H, 2, 0), "NO TIENE L3OUT" ) ) ) | Q25: =COUNTIF(Statics!F:F,Table5[[#This Row],[ID]])+COUNTIF(Statics!F:F,VALUE(Table5[[#This Row],[NODE]]))
A26: 101 | B26: 1 | C26: =VLOOKUP(VALUE(Table5[[#This Row],[NODE]]),LEAF_INFO!B:H,6,0) | D26: eth1/3 | E26: down | F26: down | G26: =VLOOKUP(_xlfn.CONCAT(Table5[[#This Row],[NODE]],Table5[[#This Row],[PORT]]),PORTS_!A:G,7,0) | I26: =VLOOKUP(VALUE(Table5[[#This Row],[NODE]]),LEAF_INFO!B:H,7,0) | J26: =ISNUMBER(SEARCH("vpc-leaf", SUBSTITUTE(LOWER(K26), "_", "-"))) | K26: =_xlfn.IFNA(VLOOKUP(VALUE(Table5[[#This Row],[NODE]]), VPC!A:A, 2, 0), "No está en VPC") | L26: =IF(OR(ISNUMBER(SEARCH("VPC-Leaf", K26)), ISNUMBER(SEARCH("VPC_Leaf", K26))),SUBSTITUTE(SUBSTITUTE(SUBSTITUTE(K26, "VPC-Leaf", ""), "VPC_Leaf", ""), "_", "-"),A26) | M26: =_xlfn.IFNA(VLOOKUP(_xlfn.CONCAT(VALUE(Table5[[#This Row],[NODE]]),Table5[[#This Row],[PORT]]),PG!C:H,6,0),"NO EXISTE PG") | N26: =_xlfn.IFNA(VLOOKUP(_xlfn.CONCAT(VALUE(Table5[[#This Row],[NODE]]),Table5[[#This Row],[PORT]]),PG!C:H,4,0),"NO EXISTE ISEL") | O26: =COUNTIF(Statics!G:G,Table5[[#This Row],[PG]])+COUNTIF(Statics!H:H,_xlfn.CONCAT((Table5[[#This Row],[NODE]]),Table5[[#This Row],[PORT]])) | P26: =_xlfn.IFNA( VLOOKUP(Table5[[#This Row],[PG]], L3OUTS!F:H, 3, 0), _xlfn.IFNA( VLOOKUP(VALUE(Table5[[#This Row],[NODE]]) & Table5[[#This Row],[PORT]], L3OUTS!G:H, 2, 0), _xlfn.IFNA( VLOOKUP(Table5[[#This Row],[PG]], L3OUTS!G:H, 2, 0), "NO TIENE L3OUT" ) ) ) | Q26: =COUNTIF(Statics!F:F,Table5[[#This Row],[ID]])+COUNTIF(Statics!F:F,VALUE(Table5[[#This Row],[NODE]]))
A27: 101 | B27: 1 | C27: =VLOOKUP(VALUE(Table5[[#This Row],[NODE]]),LEAF_INFO!B:H,6,0) | D27: eth1/4 | E27: down | F27: down | G27: =VLOOKUP(_xlfn.CONCAT(Table5[[#This Row],[NODE]],Table5[[#This Row],[PORT]]),PORTS_!A:G,7,0) | I27: =VLOOKUP(VALUE(Table5[[#This Row],[NODE]]),LEAF_INFO!B:H,7,0) | J27: =ISNUMBER(SEARCH("vpc-leaf", SUBSTITUTE(LOWER(K27), "_", "-"))) | K27: =_xlfn.IFNA(VLOOKUP(VALUE(Table5[[#This Row],[NODE]]), VPC!A:A, 2, 0), "No está en VPC") | L27: =IF(OR(ISNUMBER(SEARCH("VPC-Leaf", K27)), ISNUMBER(SEARCH("VPC_Leaf", K27))),SUBSTITUTE(SUBSTITUTE(SUBSTITUTE(K27, "VPC-Leaf", ""), "VPC_Leaf", ""), "_", "-"),A27) | M27: =_xlfn.IFNA(VLOOKUP(_xlfn.CONCAT(VALUE(Table5[[#This Row],[NODE]]),Table5[[#This Row],[PORT]]),PG!C:H,6,0),"NO EXISTE PG") | N27: =_xlfn.IFNA(VLOOKUP(_xlfn.CONCAT(VALUE(Table5[[#This Row],[NODE]]),Table5[[#This Row],[PORT]]),PG!C:H,4,0),"NO EXISTE ISEL") | O27: =COUNTIF(Statics!G:G,Table5[[#This Row],[PG]])+COUNTIF(Statics!H:H,_xlfn.CONCAT((Table5[[#This Row],[NODE]]),Table5[[#This Row],[PORT]])) | P27: =_xlfn.IFNA( VLOOKUP(Table5[[#This Row],[PG]], L3OUTS!F:H, 3, 0), _xlfn.IFNA( VLOOKUP(VALUE(Table5[[#This Row],[NODE]]) & Table5[[#This Row],[PORT]], L3OUTS!G:H, 2, 0), _xlfn.IFNA( VLOOKUP(Table5[[#This Row],[PG]], L3OUTS!G:H, 2, 0), "NO TIENE L3OUT" ) ) ) | Q27: =COUNTIF(Statics!F:F,Table5[[#This Row],[ID]])+COUNTIF(Statics!F:F,VALUE(Table5[[#This Row],[NODE]]))
A28: 101 | B28: 1 | C28: =VLOOKUP(VALUE(Table5[[#This Row],[NODE]]),LEAF_INFO!B:H,6,0) | D28: eth1/5 | E28: down | F28: down | G28: =VLOOKUP(_xlfn.CONCAT(Table5[[#This Row],[NODE]],Table5[[#This Row],[PORT]]),PORTS_!A:G,7,0) | I28: =VLOOKUP(VALUE(Table5[[#This Row],[NODE]]),LEAF_INFO!B:H,7,0) | J28: =ISNUMBER(SEARCH("vpc-leaf", SUBSTITUTE(LOWER(K28), "_", "-"))) | K28: =_xlfn.IFNA(VLOOKUP(VALUE(Table5[[#This Row],[NODE]]), VPC!A:A, 2, 0), "No está en VPC") | L28: =IF(OR(ISNUMBER(SEARCH("VPC-Leaf", K28)), ISNUMBER(SEARCH("VPC_Leaf", K28))),SUBSTITUTE(SUBSTITUTE(SUBSTITUTE(K28, "VPC-Leaf", ""), "VPC_Leaf", ""), "_", "-"),A28) | M28: =_xlfn.IFNA(VLOOKUP(_xlfn.CONCAT(VALUE(Table5[[#This Row],[NODE]]),Table5[[#This Row],[PORT]]),PG!C:H,6,0),"NO EXISTE PG") | N28: =_xlfn.IFNA(VLOOKUP(_xlfn.CONCAT(VALUE(Table5[[#This Row],[NODE]]),Table5[[#This Row],[PORT]]),PG!C:H,4,0),"NO EXISTE ISEL") | O28: =COUNTIF(Statics!G:G,Table5[[#This Row],[PG]])+COUNTIF(Statics!H:H,_xlfn.CONCAT((Table5[[#This Row],[NODE]]),Table5[[#This Row],[PORT]])) | P28: =_xlfn.IFNA( VLOOKUP(Table5[[#This Row],[PG]], L3OUTS!F:H, 3, 0), _xlfn.IFNA( VLOOKUP(VALUE(Table5[[#This Row],[NODE]]) & Table5[[#This Row],[PORT]], L3OUTS!G:H, 2, 0), _xlfn.IFNA( VLOOKUP(Table5[[#This Row],[PG]], L3OUTS!G:H, 2, 0), "NO TIENE L3OUT" ) ) ) | Q28: =COUNTIF(Statics!F:F,Table5[[#This Row],[ID]])+COUNTIF(Statics!F:F,VALUE(Table5[[#This Row],[NODE]]))
A29: 101 | B29: 1 | C29: =VLOOKUP(VALUE(Table5[[#This Row],[NODE]]),LEAF_INFO!B:H,6,0) | D29: eth1/6 | E29: down | F29: down | G29: =VLOOKUP(_xlfn.CONCAT(Table5[[#This Row],[NODE]],Table5[[#This Row],[PORT]]),PORTS_!A:G,7,0) | I29: =VLOOKUP(VALUE(Table5[[#This Row],[NODE]]),LEAF_INFO!B:H,7,0) | J29: =ISNUMBER(SEARCH("vpc-leaf", SUBSTITUTE(LOWER(K29), "_", "-"))) | K29: =_xlfn.IFNA(VLOOKUP(VALUE(Table5[[#This Row],[NODE]]), VPC!A:A, 2, 0), "No está en VPC") | L29: =IF(OR(ISNUMBER(SEARCH("VPC-Leaf", K29)), ISNUMBER(SEARCH("VPC_Leaf", K29))),SUBSTITUTE(SUBSTITUTE(SUBSTITUTE(K29, "VPC-Leaf", ""), "VPC_Leaf", ""), "_", "-"),A29) | M29: =_xlfn.IFNA(VLOOKUP(_xlfn.CONCAT(VALUE(Table5[[#This Row],[NODE]]),Table5[[#This Row],[PORT]]),PG!C:H,6,0),"NO EXISTE PG") | N29: =_xlfn.IFNA(VLOOKUP(_xlfn.CONCAT(VALUE(Table5[[#This Row],[NODE]]),Table5[[#This Row],[PORT]]),PG!C:H,4,0),"NO EXISTE ISEL") | O29: =COUNTIF(Statics!G:G,Table5[[#This Row],[PG]])+COUNTIF(Statics!H:H,_xlfn.CONCAT((Table5[[#This Row],[NODE]]),Table5[[#This Row],[PORT]])) | P29: =_xlfn.IFNA( VLOOKUP(Table5[[#This Row],[PG]], L3OUTS!F:H, 3, 0), _xlfn.IFNA( VLOOKUP(VALUE(Table5[[#This Row],[NODE]]) & Table5[[#This Row],[PORT]], L3OUTS!G:H, 2, 0), _xlfn.IFNA( VLOOKUP(Table5[[#This Row],[PG]], L3OUTS!G:H, 2, 0), "NO TIENE L3OUT" ) ) ) | Q29: =COUNTIF(Statics!F:F,Table5[[#This Row],[ID]])+COUNTIF(Statics!F:F,VALUE(Table5[[#This Row],[NODE]]))
A30: 101 | B30: 1 | C30: =VLOOKUP(VALUE(Table5[[#This Row],[NODE]]),LEAF_INFO!B:H,6,0) | D30: eth1/7 | E30: up | F30: up | G30: =VLOOKUP(_xlfn.CONCAT(Table5[[#This Row],[NODE]],Table5[[#This Row],[PORT]]),PORTS_!A:G,7,0) | H30: To_BSC_ERICCSON_01 | I30: =VLOOKUP(VALUE(Table5[[#This Row],[NODE]]),LEAF_INFO!B:H,7,0) | J30: =ISNUMBER(SEARCH("vpc-leaf", SUBSTITUTE(LOWER(K30), "_", "-"))) | K30: =_xlfn.IFNA(VLOOKUP(VALUE(Table5[[#This Row],[NODE]]), VPC!A:A, 2, 0), "No está en VPC") | L30: =IF(OR(ISNUMBER(SEARCH("VPC-Leaf", K30)), ISNUMBER(SEARCH("VPC_Leaf", K30))),SUBSTITUTE(SUBSTITUTE(SUBSTITUTE(K30, "VPC-Leaf", ""), "VPC_Leaf", ""), "_", "-"),A30) | M30: =_xlfn.IFNA(VLOOKUP(_xlfn.CONCAT(VALUE(Table5[[#This Row],[NODE]]),Table5[[#This Row],[PORT]]),PG!C:H,6,0),"NO EXISTE PG") | N30: =_xlfn.IFNA(VLOOKUP(_xlfn.CONCAT(VALUE(Table5[[#This Row],[NODE]]),Table5[[#This Row],[PORT]]),PG!C:H,4,0),"NO EXISTE ISEL") | O30: =COUNTIF(Statics!G:G,Table5[[#This Row],[PG]])+COUNTIF(Statics!H:H,_xlfn.CONCAT((Table5[[#This Row],[NODE]]),Table5[[#This Row],[PORT]])) | P30: =_xlfn.IFNA( VLOOKUP(Table5[[#This Row],[PG]], L3OUTS!F:H, 3, 0), _xlfn.IFNA( VLOOKUP(VALUE(Table5[[#This Row],[NODE]]) & Table5[[#This Row],[PORT]], L3OUTS!G:H, 2, 0), _xlfn.IFNA( VLOOKUP(Table5[[#This Row],[PG]], L3OUTS!G:H, 2, 0), "NO TIENE L3OUT" ) ) ) | Q30: =COUNTIF(Statics!F:F,Table5[[#This Row],[ID]])+COUNTIF(Statics!F:F,VALUE(Table5[[#This Row],[NODE]]))
A31: 101 | B31: 1 | C31: =VLOOKUP(VALUE(Table5[[#This Row],[NODE]]),LEAF_INFO!B:H,6,0) | D31: eth1/8 | E31: down | F31: down | G31: =VLOOKUP(_xlfn.CONCAT(Table5[[#This Row],[NODE]],Table5[[#This Row],[PORT]]),PORTS_!A:G,7,0) | I31: =VLOOKUP(VALUE(Table5[[#This Row],[NODE]]),LEAF_INFO!B:H,7,0) | J31: =ISNUMBER(SEARCH("vpc-leaf", SUBSTITUTE(LOWER(K31), "_", "-"))) | K31: =_xlfn.IFNA(VLOOKUP(VALUE(Table5[[#This Row],[NODE]]), VPC!A:A, 2, 0), "No está en VPC") | L31: =IF(OR(ISNUMBER(SEARCH("VPC-Leaf", K31)), ISNUMBER(SEARCH("VPC_Leaf", K31))),SUBSTITUTE(SUBSTITUTE(SUBSTITUTE(K31, "VPC-Leaf", ""), "VPC_Leaf", ""), "_", "-"),A31) | M31: =_xlfn.IFNA(VLOOKUP(_xlfn.CONCAT(VALUE(Table5[[#This Row],[NODE]]),Table5[[#This Row],[PORT]]),PG!C:H,6,0),"NO EXISTE PG") | N31: =_xlfn.IFNA(VLOOKUP(_xlfn.CONCAT(VALUE(Table5[[#This Row],[NODE]]),Table5[[#This Row],[PORT]]),PG!C:H,4,0),"NO EXISTE ISEL") | O31: =COUNTIF(Statics!G:G,Table5[[#This Row],[PG]])+COUNTIF(Statics!H:H,_xlfn.CONCAT((Table5[[#This Row],[NODE]]),Table5[[#This Row],[PORT]])) | P31: =_xlfn.IFNA( VLOOKUP(Table5[[#This Row],[PG]], L3OUTS!F:H, 3, 0), _xlfn.IFNA( VLOOKUP(VALUE(Table5[[#This Row],[NODE]]) & Table5[[#This Row],[PORT]], L3OUTS!G:H, 2, 0), _xlfn.IFNA( VLOOKUP(Table5[[#This Row],[PG]], L3OUTS!G:H, 2, 0), "NO TIENE L3OUT" ) ) ) | Q31: =COUNTIF(Statics!F:F,Table5[[#This Row],[ID]])+COUNTIF(Statics!F:F,VALUE(Table5[[#This Row],[NODE]]))
A32: 101 | B32: 1 | C32: =VLOOKUP(VALUE(Table5[[#This Row],[NODE]]),LEAF_INFO!B:H,6,0) | D32: eth1/9 | E32: down | F32: down | G32: =VLOOKUP(_xlfn.CONCAT(Table5[[#This Row],[NODE]],Table5[[#This Row],[PORT]]),PORTS_!A:G,7,0) | I32: =VLOOKUP(VALUE(Table5[[#This Row],[NODE]]),LEAF_INFO!B:H,7,0) | J32: =ISNUMBER(SEARCH("vpc-leaf", SUBSTITUTE(LOWER(K32), "_", "-"))) | K32: =_xlfn.IFNA(VLOOKUP(VALUE(Table5[[#This Row],[NODE]]), VPC!A:A, 2, 0), "No está en VPC") | L32: =IF(OR(ISNUMBER(SEARCH("VPC-Leaf", K32)), ISNUMBER(SEARCH("VPC_Leaf", K32))),SUBSTITUTE(SUBSTITUTE(SUBSTITUTE(K32, "VPC-Leaf", ""), "VPC_Leaf", ""), "_", "-"),A32) | M32: =_xlfn.IFNA(VLOOKUP(_xlfn.CONCAT(VALUE(Table5[[#This Row],[NODE]]),Table5[[#This Row],[PORT]]),PG!C:H,6,0),"NO EXISTE PG") | N32: =_xlfn.IFNA(VLOOKUP(_xlfn.CONCAT(VALUE(Table5[[#This Row],[NODE]]),Table5[[#This Row],[PORT]]),PG!C:H,4,0),"NO EXISTE ISEL") | O32: =COUNTIF(Statics!G:G,Table5[[#This Row],[PG]])+COUNTIF(Statics!H:H,_xlfn.CONCAT((Table5[[#This Row],[NODE]]),Table5[[#This Row],[PORT]])) | P32: =_xlfn.IFNA( VLOOKUP(Table5[[#This Row],[PG]], L3OUTS!F:H, 3, 0), _xlfn.IFNA( VLOOKUP(VALUE(Table5[[#This Row],[NODE]]) & Table5[[#This Row],[PORT]], L3OUTS!G:H, 2, 0), _xlfn.IFNA( VLOOKUP(Table5[[#This Row],[PG]], L3OUTS!G:H, 2, 0), "NO TIENE L3OUT" ) ) ) | Q32: =COUNTIF(Statics!F:F,Table5[[#This Row],[ID]])+COUNTIF(Statics!F:F,VALUE(Table5[[#This Row],[NODE]]))
A33: 101 | B33: 1 | C33: =VLOOKUP(VALUE(Table5[[#This Row],[NODE]]),LEAF_INFO!B:H,6,0) | D33: eth1/10 | E33: down | F33: down | G33: =VLOOKUP(_xlfn.CONCAT(Table5[[#This Row],[NODE]],Table5[[#This Row],[PORT]]),PORTS_!A:G,7,0) | I33: =VLOOKUP(VALUE(Table5[[#This Row],[NODE]]),LEAF_INFO!B:H,7,0) | J33: =ISNUMBER(SEARCH("vpc-leaf", SUBSTITUTE(LOWER(K33), "_", "-"))) | K33: =_xlfn.IFNA(VLOOKUP(VALUE(Table5[[#This Row],[NODE]]), VPC!A:A, 2, 0), "No está en VPC") | L33: =IF(OR(ISNUMBER(SEARCH("VPC-Leaf", K33)), ISNUMBER(SEARCH("VPC_Leaf", K33))),SUBSTITUTE(SUBSTITUTE(SUBSTITUTE(K33, "VPC-Leaf", ""), "VPC_Leaf", ""), "_", "-"),A33) | M33: =_xlfn.IFNA(VLOOKUP(_xlfn.CONCAT(VALUE(Table5[[#This Row],[NODE]]),Table5[[#This Row],[PORT]]),PG!C:H,6,0),"NO EXISTE PG") | N33: =_xlfn.IFNA(VLOOKUP(_xlfn.CONCAT(VALUE(Table5[[#This Row],[NODE]]),Table5[[#This Row],[PORT]]),PG!C:H,4,0),"NO EXISTE ISEL") | O33: =COUNTIF(Statics!G:G,Table5[[#This Row],[PG]])+COUNTIF(Statics!H:H,_xlfn.CONCAT((Table5[[#This Row],[NODE]]),Table5[[#This Row],[PORT]])) | P33: =_xlfn.IFNA( VLOOKUP(Table5[[#This Row],[PG]], L3OUTS!F:H, 3, 0), _xlfn.IFNA( VLOOKUP(VALUE(Table5[[#This Row],[NODE]]) & Table5[[#This Row],[PORT]], L3OUTS!G:H, 2, 0), _xlfn.IFNA( VLOOKUP(Table5[[#This Row],[PG]], L3OUTS!G:H, 2, 0), "NO TIENE L3OUT" ) ) ) | Q33: =COUNTIF(Statics!F:F,Table5[[#This Row],[ID]])+COUNTIF(Statics!F:F,VALUE(Table5[[#This Row],[NODE]]))
A34: 101 | B34: 1 | C34: =VLOOKUP(VALUE(Table5[[#This Row],[NODE]]),LEAF_INFO!B:H,6,0) | D34: eth1/11 | E34: up | F34: up | G34: =VLOOKUP(_xlfn.CONCAT(Table5[[#This Row],[NODE]],Table5[[#This Row],[PORT]]),PORTS_!A:G,7,0) | H34: To_PTMP-UG0-1112-0066 | I34: =VLOOKUP(VALUE(Table5[[#This Row],[NODE]]),LEAF_INFO!B:H,7,0) | J34: =ISNUMBER(SEARCH("vpc-leaf", SUBSTITUTE(LOWER(K34), "_", "-"))) | K34: =_xlfn.IFNA(VLOOKUP(VALUE(Table5[[#This Row],[NODE]]), VPC!A:A, 2, 0), "No está en VPC") | L34: =IF(OR(ISNUMBER(SEARCH("VPC-Leaf", K34)), ISNUMBER(SEARCH("VPC_Leaf", K34))),SUBSTITUTE(SUBSTITUTE(SUBSTITUTE(K34, "VPC-Leaf", ""), "VPC_Leaf", ""), "_", "-"),A34) | M34: =_xlfn.IFNA(VLOOKUP(_xlfn.CONCAT(VALUE(Table5[[#This Row],[NODE]]),Table5[[#This Row],[PORT]]),PG!C:H,6,0),"NO EXISTE PG") | N34: =_xlfn.IFNA(VLOOKUP(_xlfn.CONCAT(VALUE(Table5[[#This Row],[NODE]]),Table5[[#This Row],[PORT]]),PG!C:H,4,0),"NO EXISTE ISEL") | O34: =COUNTIF(Statics!G:G,Table5[[#This Row],[PG]])+COUNTIF(Statics!H:H,_xlfn.CONCAT((Table5[[#This Row],[NODE]]),Table5[[#This Row],[PORT]])) | P34: =_xlfn.IFNA( VLOOKUP(Table5[[#This Row],[PG]], L3OUTS!F:H, 3, 0), _xlfn.IFNA( VLOOKUP(VALUE(Table5[[#This Row],[NODE]]) & Table5[[#This Row],[PORT]], L3OUTS!G:H, 2, 0), _xlfn.IFNA( VLOOKUP(Table5[[#This Row],[PG]], L3OUTS!G:H, 2, 0), "NO TIENE L3OUT" ) ) ) | Q34: =COUNTIF(Statics!F:F,Table5[[#This Row],[ID]])+COUNTIF(Statics!F:F,VALUE(Table5[[#This Row],[NODE]]))
A35: 101 | B35: 1 | C35: =VLOOKUP(VALUE(Table5[[#This Row],[NODE]]),LEAF_INFO!B:H,6,0) | D35: eth1/12 | E35: up | F35: up | G35: =VLOOKUP(_xlfn.CONCAT(Table5[[#This Row],[NODE]],Table5[[#This Row],[PORT]]),PORTS_!A:G,7,0) | H35: LINK_HACIA_To_PTMP-UG0-1112-0140 | I35: =VLOOKUP(VALUE(Table5[[#This Row],[NODE]]),LEAF_INFO!B:H,7,0) | J35: =ISNUMBER(SEARCH("vpc-leaf", SUBSTITUTE(LOWER(K35), "_", "-"))) | K35: =_xlfn.IFNA(VLOOKUP(VALUE(Table5[[#This Row],[NODE]]), VPC!A:A, 2, 0), "No está en VPC") | L35: =IF(OR(ISNUMBER(SEARCH("VPC-Leaf", K35)), ISNUMBER(SEARCH("VPC_Leaf", K35))),SUBSTITUTE(SUBSTITUTE(SUBSTITUTE(K35, "VPC-Leaf", ""), "VPC_Leaf", ""), "_", "-"),A35) | M35: =_xlfn.IFNA(VLOOKUP(_xlfn.CONCAT(VALUE(Table5[[#This Row],[NODE]]),Table5[[#This Row],[PORT]]),PG!C:H,6,0),"NO EXISTE PG") | N35: =_xlfn.IFNA(VLOOKUP(_xlfn.CONCAT(VALUE(Table5[[#This Row],[NODE]]),Table5[[#This Row],[PORT]]),PG!C:H,4,0),"NO EXISTE ISEL") | O35: =COUNTIF(Statics!G:G,Table5[[#This Row],[PG]])+COUNTIF(Statics!H:H,_xlfn.CONCAT((Table5[[#This Row],[NODE]]),Table5[[#This Row],[PORT]])) | P35: =_xlfn.IFNA( VLOOKUP(Table5[[#This Row],[PG]], L3OUTS!F:H, 3, 0), _xlfn.IFNA( VLOOKUP(VALUE(Table5[[#This Row],[NODE]]) & Table5[[#This Row],[PORT]], L3OUTS!G:H, 2, 0), _xlfn.IFNA( VLOOKUP(Table5[[#This Row],[PG]], L3OUTS!G:H, 2, 0), "NO TIENE L3OUT" ) ) ) | Q35: =COUNTIF(Statics!F:F,Table5[[#This Row],[ID]])+COUNTIF(Statics!F:F,VALUE(Table5[[#This Row],[NODE]]))
A36: 101 | B36: 1 | C36: =VLOOKUP(VALUE(Table5[[#This Row],[NODE]]),LEAF_INFO!B:H,6,0) | D36: eth1/13 | E36: up | F36: up | G36: =VLOOKUP(_xlfn.CONCAT(Table5[[#This Row],[NODE]],Table5[[#This Row],[PORT]]),PORTS_!A:G,7,0) | H36: To_EVO1_INGEV1 | I36: =VLOOKUP(VALUE(Table5[[#This Row],[NODE]]),LEAF_INFO!B:H,7,0) | J36: =ISNUMBER(SEARCH("vpc-leaf", SUBSTITUTE(LOWER(K36), "_", "-"))) | K36: =_xlfn.IFNA(VLOOKUP(VALUE(Table5[[#This Row],[NODE]]), VPC!A:A, 2, 0), "No está en VPC") | L36: =IF(OR(ISNUMBER(SEARCH("VPC-Leaf", K36)), ISNUMBER(SEARCH("VPC_Leaf", K36))),SUBSTITUTE(SUBSTITUTE(SUBSTITUTE(K36, "VPC-Leaf", ""), "VPC_Leaf", ""), "_", "-"),A36) | M36: =_xlfn.IFNA(VLOOKUP(_xlfn.CONCAT(VALUE(Table5[[#This Row],[NODE]]),Table5[[#This Row],[PORT]]),PG!C:H,6,0),"NO EXISTE PG") | N36: =_xlfn.IFNA(VLOOKUP(_xlfn.CONCAT(VALUE(Table5[[#This Row],[NODE]]),Table5[[#This Row],[PORT]]),PG!C:H,4,0),"NO EXISTE ISEL") | O36: =COUNTIF(Statics!G:G,Table5[[#This Row],[PG]])+COUNTIF(Statics!H:H,_xlfn.CONCAT((Table5[[#This Row],[NODE]]),Table5[[#This Row],[PORT]])) | P36: =_xlfn.IFNA( VLOOKUP(Table5[[#This Row],[PG]], L3OUTS!F:H, 3, 0), _xlfn.IFNA( VLOOKUP(VALUE(Table5[[#This Row],[NODE]]) & Table5[[#This Row],[PORT]], L3OUTS!G:H, 2, 0), _xlfn.IFNA( VLOOKUP(Table5[[#This Row],[PG]], L3OUTS!G:H, 2, 0), "NO TIENE L3OUT" ) ) ) | Q36: =COUNTIF(Statics!F:F,Table5[[#This Row],[ID]])+COUNTIF(Statics!F:F,VALUE(Table5[[#This Row],[NODE]]))
A37: 101 | B37: 1 | C37: =VLOOKUP(VALUE(Table5[[#This Row],[NODE]]),LEAF_INFO!B:H,6,0) | D37: eth1/14 | E37: up | F37: up | G37: =VLOOKUP(_xlfn.CONCAT(Table5[[#This Row],[NODE]],Table5[[#This Row],[PORT]]),PORTS_!A:G,7,0) | H37: Hacia NR 5G INGENIEROS | I37: =VLOOKUP(VALUE(Table5[[#This Row],[NODE]]),LEAF_INFO!B:H,7,0) | J37: =ISNUMBER(SEARCH("vpc-leaf", SUBSTITUTE(LOWER(K37), "_", "-"))) | K37: =_xlfn.IFNA(VLOOKUP(VALUE(Table5[[#This Row],[NODE]]), VPC!A:A, 2, 0), "No está en VPC") | L37: =IF(OR(ISNUMBER(SEARCH("VPC-Leaf", K37)), ISNUMBER(SEARCH("VPC_Leaf", K37))),SUBSTITUTE(SUBSTITUTE(SUBSTITUTE(K37, "VPC-Leaf", ""), "VPC_Leaf", ""), "_", "-"),A37) | M37: =_xlfn.IFNA(VLOOKUP(_xlfn.CONCAT(VALUE(Table5[[#This Row],[NODE]]),Table5[[#This Row],[PORT]]),PG!C:H,6,0),"NO EXISTE PG") | N37: =_xlfn.IFNA(VLOOKUP(_xlfn.CONCAT(VALUE(Table5[[#This Row],[NODE]]),Table5[[#This Row],[PORT]]),PG!C:H,4,0),"NO EXISTE ISEL") | O37: =COUNTIF(Statics!G:G,Table5[[#This Row],[PG]])+COUNTIF(Statics!H:H,_xlfn.CONCAT((Table5[[#This Row],[NODE]]),Table5[[#This Row],[PORT]])) | P37: =_xlfn.IFNA( VLOOKUP(Table5[[#This Row],[PG]], L3OUTS!F:H, 3, 0), _xlfn.IFNA( VLOOKUP(VALUE(Table5[[#This Row],[NODE]]) & Table5[[#This Row],[PORT]], L3OUTS!G:H, 2, 0), _xlfn.IFNA( VLOOKUP(Table5[[#This Row],[PG]], L3OUTS!G:H, 2, 0), "NO TIENE L3OUT" ) ) ) | Q37: =COUNTIF(Statics!F:F,Table5[[#This Row],[ID]])+COUNTIF(Statics!F:F,VALUE(Table5[[#This Row],[NODE]]))
A38: 101 | B38: 1 | C38: =VLOOKUP(VALUE(Table5[[#This Row],[NODE]]),LEAF_INFO!B:H,6,0) | D38: eth1/15 | E38: down | F38: down | G38: =VLOOKUP(_xlfn.CONCAT(Table5[[#This Row],[NODE]],Table5[[#This Row],[PORT]]),PORTS_!A:G,7,0) | I38: =VLOOKUP(VALUE(Table5[[#This Row],[NODE]]),LEAF_INFO!B:H,7,0) | J38: =ISNUMBER(SEARCH("vpc-leaf", SUBSTITUTE(LOWER(K38), "_", "-"))) | K38: =_xlfn.IFNA(VLOOKUP(VALUE(Table5[[#This Row],[NODE]]), VPC!A:A, 2, 0), "No está en VPC") | L38: =IF(OR(ISNUMBER(SEARCH("VPC-Leaf", K38)), ISNUMBER(SEARCH("VPC_Leaf", K38))),SUBSTITUTE(SUBSTITUTE(SUBSTITUTE(K38, "VPC-Leaf", ""), "VPC_Leaf", ""), "_", "-"),A38) | M38: =_xlfn.IFNA(VLOOKUP(_xlfn.CONCAT(VALUE(Table5[[#This Row],[NODE]]),Table5[[#This Row],[PORT]]),PG!C:H,6,0),"NO EXISTE PG") | N38: =_xlfn.IFNA(VLOOKUP(_xlfn.CONCAT(VALUE(Table5[[#This Row],[NODE]]),Table5[[#This Row],[PORT]]),PG!C:H,4,0),"NO EXISTE ISEL") | O38: =COUNTIF(Statics!G:G,Table5[[#This Row],[PG]])+COUNTIF(Statics!H:H,_xlfn.CONCAT((Table5[[#This Row],[NODE]]),Table5[[#This Row],[PORT]])) | P38: =_xlfn.IFNA( VLOOKUP(Table5[[#This Row],[PG]], L3OUTS!F:H, 3, 0), _xlfn.IFNA( VLOOKUP(VALUE(Table5[[#This Row],[NODE]]) & Table5[[#This Row],[PORT]], L3OUTS!G:H, 2, 0), _xlfn.IFNA( VLOOKUP(Table5[[#This Row],[PG]], L3OUTS!G:H, 2, 0), "NO TIENE L3OUT" ) ) ) | Q38: =COUNTIF(Statics!F:F,Table5[[#This Row],[ID]])+COUNTIF(Statics!F:F,VALUE(Table5[[#This Row],[NODE]]))
A39: 101 | B39: 1 | C39: =VLOOKUP(VALUE(Table5[[#This Row],[NODE]]),LEAF_INFO!B:H,6,0) | D39: eth1/16 | E39: down | F39: down | G39: =VLOOKUP(_xlfn.CONCAT(Table5[[#This Row],[NODE]],Table5[[#This Row],[PORT]]),PORTS_!A:G,7,0) | I39: =VLOOKUP(VALUE(Table5[[#This Row],[NODE]]),LEAF_INFO!B:H,7,0) | J39: =ISNUMBER(SEARCH("vpc-leaf", SUBSTITUTE(LOWER(K39), "_", "-"))) | K39: =_xlfn.IFNA(VLOOKUP(VALUE(Table5[[#This Row],[NODE]]), VPC!A:A, 2, 0), "No está en VPC") | L39: =IF(OR(ISNUMBER(SEARCH("VPC-Leaf", K39)), ISNUMBER(SEARCH("VPC_Leaf", K39))),SUBSTITUTE(SUBSTITUTE(SUBSTITUTE(K39, "VPC-Leaf", ""), "VPC_Leaf", ""), "_", "-"),A39) | M39: =_xlfn.IFNA(VLOOKUP(_xlfn.CONCAT(VALUE(Table5[[#This Row],[NODE]]),Table5[[#This Row],[PORT]]),PG!C:H,6,0),"NO EXISTE PG") | N39: =_xlfn.IFNA(VLOOKUP(_xlfn.CONCAT(VALUE(Table5[[#This Row],[NODE]]),Table5[[#This Row],[PORT]]),PG!C:H,4,0),"NO EXISTE ISEL") | O39: =COUNTIF(Statics!G:G,Table5[[#This Row],[PG]])+COUNTIF(Statics!H:H,_xlfn.CONCAT((Table5[[#This Row],[NODE]]),Table5[[#This Row],[PORT]])) | P39: =_xlfn.IFNA( VLOOKUP(Table5[[#This Row],[PG]], L3OUTS!F:H, 3, 0), _xlfn.IFNA( VLOOKUP(VALUE(Table5[[#This Row],[NODE]]) & Table5[[#This Row],[PORT]], L3OUTS!G:H, 2, 0), _xlfn.IFNA( VLOOKUP(Table5[[#This Row],[PG]], L3OUTS!G:H, 2, 0), "NO TIENE L3OUT" ) ) ) | Q39: =COUNTIF(Statics!F:F,Table5[[#This Row],[ID]])+COUNTIF(Statics!F:F,VALUE(Table5[[#This Row],[NODE]]))
A40: 101 | B40: 1 | C40: =VLOOKUP(VALUE(Table5[[#This Row],[NODE]]),LEAF_INFO!B:H,6,0) | D40: eth1/17 | E40: down | F40: down | G40: =VLOOKUP(_xlfn.CONCAT(Table5[[#This Row],[NODE]],Table5[[#This Row],[PORT]]),PORTS_!A:G,7,0) | I40: =VLOOKUP(VALUE(Table5[[#This Row],[NODE]]),LEAF_INFO!B:H,7,0) | J40: =ISNUMBER(SEARCH("vpc-leaf", SUBSTITUTE(LOWER(K40), "_", "-"))) | K40: =_xlfn.IFNA(VLOOKUP(VALUE(Table5[[#This Row],[NODE]]), VPC!A:A, 2, 0), "No está en VPC") | L40: =IF(OR(ISNUMBER(SEARCH("VPC-Leaf", K40)), ISNUMBER(SEARCH("VPC_Leaf", K40))),SUBSTITUTE(SUBSTITUTE(SUBSTITUTE(K40, "VPC-Leaf", ""), "VPC_Leaf", ""), "_", "-"),A40) | M40: =_xlfn.IFNA(VLOOKUP(_xlfn.CONCAT(VALUE(Table5[[#This Row],[NODE]]),Table5[[#This Row],[PORT]]),PG!C:H,6,0),"NO EXISTE PG") | N40: =_xlfn.IFNA(VLOOKUP(_xlfn.CONCAT(VALUE(Table5[[#This Row],[NODE]]),Table5[[#This Row],[PORT]]),PG!C:H,4,0),"NO EXISTE ISEL") | O40: =COUNTIF(Statics!G:G,Table5[[#This Row],[PG]])+COUNTIF(Statics!H:H,_xlfn.CONCAT((Table5[[#This Row],[NODE]]),Table5[[#This Row],[PORT]])) | P40: =_xlfn.IFNA( VLOOKUP(Table5[[#This Row],[PG]], L3OUTS!F:H, 3, 0), _xlfn.IFNA( VLOOKUP(VALUE(Table5[[#This Row],[NODE]]) & Table5[[#This Row],[PORT]], L3OUTS!G:H, 2, 0), _xlfn.IFNA( VLOOKUP(Table5[[#This Row],[PG]], L3OUTS!G:H, 2, 0), "NO TIENE L3OUT" ) ) ) | Q40: =COUNTIF(Statics!F:F,Table5[[#This Row],[ID]])+COUNTIF(Statics!F:F,VALUE(Table5[[#This Row],[NODE]]))
...

Sheet L3OUTS
A1: DN | B1: Tenant | C1: L3Out Name | D1: POD | E1: leaf | F1: PORT | G1: concat | H1: L3Out Name
A2: uni/tn-TELCEL_TELCO_NETWORK/out-L3OUT_UG0-1208-0008/lnodep-NP_LF_102/lifp-INTP_LF_102_SO6312/rspathL3OutAtt-[topology/pod-1/paths-102/pathep-[eth1/9]] | B2: =_xlfn.TEXTBEFORE(_xlfn.TEXTAFTER(A2, "tn-"), "/") | C2: =_xlfn.TEXTBEFORE(_xlfn.TEXTAFTER(A2, "out-"), "/") | D2: =_xlfn.TEXTBEFORE(_xlfn.TEXTAFTER(A2, "topology/pod-"), "/") | E2: =_xlfn.TEXTBEFORE(_xlfn.TEXTAFTER(A2, "paths-"), "/") | F2: =_xlfn.TEXTBEFORE(_xlfn.TEXTAFTER(A2, "pathep-["), "]") | G2: =IF(ISNUMBER(SEARCH("PG",F2)),F2,_xlfn.CONCAT(E2,F2)) | H2: =C2
A3: uni/tn-TELCEL_TELCO_NETWORK/out-L3OUT_RED_GPRS_GN_RMAC/lnodep-NP_LF_101/lifp-INTP_LF_101/rspathL3OutAtt-[topology/pod-1/paths-101/pathep-[PG_PC_101_L3_RMAC1]] | B3: =_xlfn.TEXTBEFORE(_xlfn.TEXTAFTER(A3, "tn-"), "/") | C3: =_xlfn.TEXTBEFORE(_xlfn.TEXTAFTER(A3, "out-"), "/") | D3: =_xlfn.TEXTBEFORE(_xlfn.TEXTAFTER(A3, "topology/pod-"), "/") | E3: =_xlfn.TEXTBEFORE(_xlfn.TEXTAFTER(A3, "paths-"), "/") | F3: =_xlfn.TEXTBEFORE(_xlfn.TEXTAFTER(A3, "pathep-["), "]") | G3: =IF(ISNUMBER(SEARCH("PG",F3)),F3,_xlfn.CONCAT(E3,F3)) | H3: =C3
